Workbook

Sheet Monthly Summary
A1: 🇦🇪 AED ⇄ 🇮🇳 INR — Monthly Summary (January)
A2: Pulled automatically from the daily sheets · losses are shown as negative amounts · Net = Profit + Loss · click a day to open its sheet
A4: Day | B4: AED Received | C4: INR Given | D4: Profit | E4: Loss | F4: Net Profit/Loss | G4: Transactions
A5: 01-Jan | B5: ='01-Jan'!D47 -> 0 | C5: ='01-Jan'!D48 -> 0 | D5: ='01-Jan'!D49 -> 0 | E5: ='01-Jan'!D50 -> 0 | F5: ='01-Jan'!D51 -> 0 | G5: ='01-Jan'!D52 -> 0
A6: 02-Jan | B6: ='02-Jan'!D47 -> 0 | C6: ='02-Jan'!D48 -> 0 | D6: ='02-Jan'!D49 -> 0 | E6: ='02-Jan'!D50 -> 0 | F6: ='02-Jan'!D51 -> 0 | G6: ='02-Jan'!D52 -> 0
A7: 03-Jan | B7: ='03-Jan'!D47 -> 0 | C7: ='03-Jan'!D48 -> 0 | D7: ='03-Jan'!D49 -> 0 | E7: ='03-Jan'!D50 -> 0 | F7: ='03-Jan'!D51 -> 0 | G7: ='03-Jan'!D52 -> 0
A8: 04-Jan | B8: ='04-Jan'!D47 -> 0 | C8: ='04-Jan'!D48 -> 0 | D8: ='04-Jan'!D49 -> 0 | E8: ='04-Jan'!D50 -> 0 | F8: ='04-Jan'!D51 -> 0 | G8: ='04-Jan'!D52 -> 0
A9: 05-Jan | B9: ='05-Jan'!D47 -> 0 | C9: ='05-Jan'!D48 -> 0 | D9: ='05-Jan'!D49 -> 0 | E9: ='05-Jan'!D50 -> 0 | F9: ='05-Jan'!D51 -> 0 | G9: ='05-Jan'!D52 -> 0
A10: 06-Jan | B10: ='06-Jan'!D47 -> 0 | C10: ='06-Jan'!D48 -> 0 | D10: ='06-Jan'!D49 -> 0 | E10: ='06-Jan'!D50 -> 0 | F10: ='06-Jan'!D51 -> 0 | G10: ='06-Jan'!D52 -> 0
A11: 07-Jan | B11: ='07-Jan'!D47 -> 0 | C11: ='07-Jan'!D48 -> 0 | D11: ='07-Jan'!D49 -> 0 | E11: ='07-Jan'!D50 -> 0 | F11: ='07-Jan'!D51 -> 0 | G11: ='07-Jan'!D52 -> 0
A12: 08-Jan | B12: ='08-Jan'!D47 -> 0 | C12: ='08-Jan'!D48 -> 0 | D12: ='08-Jan'!D49 -> 0 | E12: ='08-Jan'!D50 -> 0 | F12: ='08-Jan'!D51 -> 0 | G12: ='08-Jan'!D52 -> 0
A13: 09-Jan | B13: ='09-Jan'!D47 -> 0 | C13: ='09-Jan'!D48 -> 0 | D13: ='09-Jan'!D49 -> 0 | E13: ='09-Jan'!D50 -> 0 | F13: ='09-Jan'!D51 -> 0 | G13: ='09-Jan'!D52 -> 0
A14: 10-Jan | B14: ='10-Jan'!D47 -> 0 | C14: ='10-Jan'!D48 -> 0 | D14: ='10-Jan'!D49 -> 0 | E14: ='10-Jan'!D50 -> 0 | F14: ='10-Jan'!D51 -> 0 | G14: ='10-Jan'!D52 -> 0
A15: 11-Jan | B15: ='11-Jan'!D47 -> 0 | C15: ='11-Jan'!D48 -> 0 | D15: ='11-Jan'!D49 -> 0 | E15: ='11-Jan'!D50 -> 0 | F15: ='11-Jan'!D51 -> 0 | G15: ='11-Jan'!D52 -> 0
A16: 12-Jan | B16: ='12-Jan'!D47 -> 0 | C16: ='12-Jan'!D48 -> 0 | D16: ='12-Jan'!D49 -> 0 | E16: ='12-Jan'!D50 -> 0 | F16: ='12-Jan'!D51 -> 0 | G16: ='12-Jan'!D52 -> 0
A17: 13-Jan | B17: ='13-Jan'!D47 -> 0 | C17: ='13-Jan'!D48 -> 0 | D17: ='13-Jan'!D49 -> 0 | E17: ='13-Jan'!D50 -> 0 | F17: ='13-Jan'!D51 -> 0 | G17: ='13-Jan'!D52 -> 0
A18: 14-Jan | B18: ='14-Jan'!D47 -> 0 | C18: ='14-Jan'!D48 -> 0 | D18: ='14-Jan'!D49 -> 0 | E18: ='14-Jan'!D50 -> 0 | F18: ='14-Jan'!D51 -> 0 | G18: ='14-Jan'!D52 -> 0
A19: 15-Jan | B19: ='15-Jan'!D47 -> 0 | C19: ='15-Jan'!D48 -> 0 | D19: ='15-Jan'!D49 -> 0 | E19: ='15-Jan'!D50 -> 0 | F19: ='15-Jan'!D51 -> 0 | G19: ='15-Jan'!D52 -> 0
A20: 16-Jan | B20: ='16-Jan'!D47 -> 0 | C20: ='16-Jan'!D48 -> 0 | D20: ='16-Jan'!D49 -> 0 | E20: ='16-Jan'!D50 -> 0 | F20: ='16-Jan'!D51 -> 0 | G20: ='16-Jan'!D52 -> 0
A21: 17-Jan | B21: ='17-Jan'!D47 -> 0 | C21: ='17-Jan'!D48 -> 0 | D21: ='17-Jan'!D49 -> 0 | E21: ='17-Jan'!D50 -> 0 | F21: ='17-Jan'!D51 -> 0 | G21: ='17-Jan'!D52 -> 0
A22: 18-Jan | B22: ='18-Jan'!D47 -> 0 | C22: ='18-Jan'!D48 -> 0 | D22: ='18-Jan'!D49 -> 0 | E22: ='18-Jan'!D50 -> 0 | F22: ='18-Jan'!D51 -> 0 | G22: ='18-Jan'!D52 -> 0
A23: 19-Jan | B23: ='19-Jan'!D47 -> 0 | C23: ='19-Jan'!D48 -> 0 | D23: ='19-Jan'!D49 -> 0 | E23: ='19-Jan'!D50 -> 0 | F23: ='19-Jan'!D51 -> 0 | G23: ='19-Jan'!D52 -> 0
A24: 20-Jan | B24: ='20-Jan'!D47 -> 0 | C24: ='20-Jan'!D48 -> 0 | D24: ='20-Jan'!D49 -> 0 | E24: ='20-Jan'!D50 -> 0 | F24: ='20-Jan'!D51 -> 0 | G24: ='20-Jan'!D52 -> 0
A25: 21-Jan | B25: ='21-Jan'!D47 -> 0 | C25: ='21-Jan'!D48 -> 0 | D25: ='21-Jan'!D49 -> 0 | E25: ='21-Jan'!D50 -> 0 | F25: ='21-Jan'!D51 -> 0 | G25: ='21-Jan'!D52 -> 0
A26: 22-Jan | B26: ='22-Jan'!D47 -> 0 | C26: ='22-Jan'!D48 -> 0 | D26: ='22-Jan'!D49 -> 0 | E26: ='22-Jan'!D50 -> 0 | F26: ='22-Jan'!D51 -> 0 | G26: ='22-Jan'!D52 -> 0
A27: 23-Jan | B27: ='23-Jan'!D47 -> 0 | C27: ='23-Jan'!D48 -> 0 | D27: ='23-Jan'!D49 -> 0 | E27: ='23-Jan'!D50 -> 0 | F27: ='23-Jan'!D51 -> 0 | G27: ='23-Jan'!D52 -> 0
A28: 24-Jan | B28: ='24-Jan'!D47 -> 0 | C28: ='24-Jan'!D48 -> 0 | D28: ='24-Jan'!D49 -> 0 | E28: ='24-Jan'!D50 -> 0 | F28: ='24-Jan'!D51 -> 0 | G28: ='24-Jan'!D52 -> 0
A29: 25-Jan | B29: ='25-Jan'!D47 -> 0 | C29: ='25-Jan'!D48 -> 0 | D29: ='25-Jan'!D49 -> 0 | E29: ='25-Jan'!D50 -> 0 | F29: ='25-Jan'!D51 -> 0 | G29: ='25-Jan'!D52 -> 0
A30: 26-Jan | B30: ='26-Jan'!D47 -> 0 | C30: ='26-Jan'!D48 -> 0 | D30: ='26-Jan'!D49 -> 0 | E30: ='26-Jan'!D50 -> 0 | F30: ='26-Jan'!D51 -> 0 | G30: ='26-Jan'!D52 -> 0
A31: 27-Jan | B31: ='27-Jan'!D47 -> 0 | C31: ='27-Jan'!D48 -> 0 | D31: ='27-Jan'!D49 -> 0 | E31: ='27-Jan'!D50 -> 0 | F31: ='27-Jan'!D51 -> 0 | G31: ='27-Jan'!D52 -> 0
A32: 28-Jan | B32: ='28-Jan'!D47 -> 0 | C32: ='28-Jan'!D48 -> 0 | D32: ='28-Jan'!D49 -> 0 | E32: ='28-Jan'!D50 -> 0 | F32: ='28-Jan'!D51 -> 0 | G32: ='28-Jan'!D52 -> 0
A33: 29-Jan | B33: ='29-Jan'!D47 -> 0 | C33: ='29-Jan'!D48 -> 0 | D33: ='29-Jan'!D49 -> 0 | E33: ='29-Jan'!D50 -> 0 | F33: ='29-Jan'!D51 -> 0 | G33: ='29-Jan'!D52 -> 0
A34: 30-Jan | B34: ='30-Jan'!D47 -> 0 | C34: ='30-Jan'!D48 -> 0 | D34: ='30-Jan'!D49 -> 0 | E34: ='30-Jan'!D50 -> 0 | F34: ='30-Jan'!D51 -> 0 | G34: ='30-Jan'!D52 -> 0
A35: 31-Jan | B35: ='31-Jan'!D47 -> 0 | C35: ='31-Jan'!D48 -> 0 | D35: ='31-Jan'!D49 -> 0 | E35: ='31-Jan'!D50 -> 0 | F35: ='31-Jan'!D51 -> 0 | G35: ='31-Jan'!D52 -> 0
A36: MONTH TOTAL | B36: =SUM(B5:B35) -> 0 | C36: =SUM(C5:C35) -> 0 | D36: =SUM(D5:D35) -> 0 | E36: =SUM(E5:E35) -> 0 | F36: =SUM(F5:F35) -> 0 | G36: =SUM(G5:G35) -> 0

Sheet 01-Jan
A1: 🇦🇪 AED — UAE Dirham | C1: 🇮🇳 INR — Indian Rupee
A2: EXCHANGE RATE | B2: 1 AED = | D2: =IF(N(C2)>0,"","◄ enter today's rate") -> ◄ enter today's rate
A3: Yellow cell and blue figures are yours to type; everything else calculates automatically. Profit / Loss = AED Received × Rate − INR Given (100 AED at 25, ₹2,400 given → +₹100)
A4: Name | B4: AED Received | C4: INR Given | D4: Profit / Loss
D5: =IF(AND(ISNUMBER(B5),ISNUMBER(C5),N($C$2)>0),ROUND(B5*$C$2-C5,2),"")
D6: =IF(AND(ISNUMBER(B6),ISNUMBER(C6),N($C$2)>0),ROUND(B6*$C$2-C6,2),"")
D7: =IF(AND(ISNUMBER(B7),ISNUMBER(C7),N($C$2)>0),ROUND(B7*$C$2-C7,2),"")
D8: =IF(AND(ISNUMBER(B8),ISNUMBER(C8),N($C$2)>0),ROUND(B8*$C$2-C8,2),"")
D9: =IF(AND(ISNUMBER(B9),ISNUMBER(C9),N($C$2)>0),ROUND(B9*$C$2-C9,2),"")
D10: =IF(AND(ISNUMBER(B10),ISNUMBER(C10),N($C$2)>0),ROUND(B10*$C$2-C10,2),"")
D11: =IF(AND(ISNUMBER(B11),ISNUMBER(C11),N($C$2)>0),ROUND(B11*$C$2-C11,2),"")
D12: =IF(AND(ISNUMBER(B12),ISNUMBER(C12),N($C$2)>0),ROUND(B12*$C$2-C12,2),"")
D13: =IF(AND(ISNUMBER(B13),ISNUMBER(C13),N($C$2)>0),ROUND(B13*$C$2-C13,2),"")
D14: =IF(AND(ISNUMBER(B14),ISNUMBER(C14),N($C$2)>0),ROUND(B14*$C$2-C14,2),"")
D15: =IF(AND(ISNUMBER(B15),ISNUMBER(C15),N($C$2)>0),ROUND(B15*$C$2-C15,2),"")
D16: =IF(AND(ISNUMBER(B16),ISNUMBER(C16),N($C$2)>0),ROUND(B16*$C$2-C16,2),"")
... D44: =IF(AND(ISNUMBER(B44),ISNUMBER(C44),N($C$2)>0),ROUND(B44*$C$2-C44,2),"")
A46: DAILY TOTALS
A47: Total AED Received | D47: =SUM(B5:B44) -> 0
A48: Total INR Given | D48: =SUM(C5:C44) -> 0
A49: Total Profit | D49: =SUMIF(D5:D44,">0") -> 0
A50: Total Loss | D50: =SUMIF(D5:D44,"<0") -> 0
A51: Net Profit/Loss | D51: =SUM(D5:D44) -> 0
A52: Number of Transactions | D52: =SUMPRODUCT(--((ISNUMBER(B5:B44)+ISNUMBER(C5:C44))>0)) -> 0

Sheet 02-Jan
A1: 🇦🇪 AED — UAE Dirham | C1: 🇮🇳 INR — Indian Rupee
A2: EXCHANGE RATE | B2: 1 AED = | D2: =IF(N(C2)>0,"","◄ enter today's rate") -> ◄ enter today's rate
A3: Yellow cell and blue figures are yours to type; everything else calculates automatically. Profit / Loss = AED Received × Rate − INR Given (100 AED at 25, ₹2,400 given → +₹100)
A4: Name | B4: AED Received | C4: INR Given | D4: Profit / Loss
D5: =IF(AND(ISNUMBER(B5),ISNUMBER(C5),N($C$2)>0),ROUND(B5*$C$2-C5,2),"")
D6: =IF(AND(ISNUMBER(B6),ISNUMBER(C6),N($C$2)>0),ROUND(B6*$C$2-C6,2),"")
D7: =IF(AND(ISNUMBER(B7),ISNUMBER(C7),N($C$2)>0),ROUND(B7*$C$2-C7,2),"")
D8: =IF(AND(ISNUMBER(B8),ISNUMBER(C8),N($C$2)>0),ROUND(B8*$C$2-C8,2),"")
D9: =IF(AND(ISNUMBER(B9),ISNUMBER(C9),N($C$2)>0),ROUND(B9*$C$2-C9,2),"")
D10: =IF(AND(ISNUMBER(B10),ISNUMBER(C10),N($C$2)>0),ROUND(B10*$C$2-C10,2),"")
D11: =IF(AND(ISNUMBER(B11),ISNUMBER(C11),N($C$2)>0),ROUND(B11*$C$2-C11,2),"")
D12: =IF(AND(ISNUMBER(B12),ISNUMBER(C12),N($C$2)>0),ROUND(B12*$C$2-C12,2),"")
D13: =IF(AND(ISNUMBER(B13),ISNUMBER(C13),N($C$2)>0),ROUND(B13*$C$2-C13,2),"")
D14: =IF(AND(ISNUMBER(B14),ISNUMBER(C14),N($C$2)>0),ROUND(B14*$C$2-C14,2),"")
D15: =IF(AND(ISNUMBER(B15),ISNUMBER(C15),N($C$2)>0),ROUND(B15*$C$2-C15,2),"")
D16: =IF(AND(ISNUMBER(B16),ISNUMBER(C16),N($C$2)>0),ROUND(B16*$C$2-C16,2),"")
... D44: =IF(AND(ISNUMBER(B44),ISNUMBER(C44),N($C$2)>0),ROUND(B44*$C$2-C44,2),"")
A46: DAILY TOTALS
A47: Total AED Received | D47: =SUM(B5:B44) -> 0
A48: Total INR Given | D48: =SUM(C5:C44) -> 0
A49: Total Profit | D49: =SUMIF(D5:D44,">0") -> 0
A50: Total Loss | D50: =SUMIF(D5:D44,"<0") -> 0
A51: Net Profit/Loss | D51: =SUM(D5:D44) -> 0
A52: Number of Transactions | D52: =SUMPRODUCT(--((ISNUMBER(B5:B44)+ISNUMBER(C5:C44))>0)) -> 0

Sheet 03-Jan
A1: 🇦🇪 AED — UAE Dirham | C1: 🇮🇳 INR — Indian Rupee
A2: EXCHANGE RATE | B2: 1 AED = | D2: =IF(N(C2)>0,"","◄ enter today's rate") -> ◄ enter today's rate
A3: Yellow cell and blue figures are yours to type; everything else calculates automatically. Profit / Loss = AED Received × Rate − INR Given (100 AED at 25, ₹2,400 given → +₹100)
A4: Name | B4: AED Received | C4: INR Given | D4: Profit / Loss
D5: =IF(AND(ISNUMBER(B5),ISNUMBER(C5),N($C$2)>0),ROUND(B5*$C$2-C5,2),"")
D6: =IF(AND(ISNUMBER(B6),ISNUMBER(C6),N($C$2)>0),ROUND(B6*$C$2-C6,2),"")
D7: =IF(AND(ISNUMBER(B7),ISNUMBER(C7),N($C$2)>0),ROUND(B7*$C$2-C7,2),"")
D8: =IF(AND(ISNUMBER(B8),ISNUMBER(C8),N($C$2)>0),ROUND(B8*$C$2-C8,2),"")
D9: =IF(AND(ISNUMBER(B9),ISNUMBER(C9),N($C$2)>0),ROUND(B9*$C$2-C9,2),"")
D10: =IF(AND(ISNUMBER(B10),ISNUMBER(C10),N($C$2)>0),ROUND(B10*$C$2-C10,2),"")
D11: =IF(AND(ISNUMBER(B11),ISNUMBER(C11),N($C$2)>0),ROUND(B11*$C$2-C11,2),"")
D12: =IF(AND(ISNUMBER(B12),ISNUMBER(C12),N($C$2)>0),ROUND(B12*$C$2-C12,2),"")
D13: =IF(AND(ISNUMBER(B13),ISNUMBER(C13),N($C$2)>0),ROUND(B13*$C$2-C13,2),"")
D14: =IF(AND(ISNUMBER(B14),ISNUMBER(C14),N($C$2)>0),ROUND(B14*$C$2-C14,2),"")
D15: =IF(AND(ISNUMBER(B15),ISNUMBER(C15),N($C$2)>0),ROUND(B15*$C$2-C15,2),"")
D16: =IF(AND(ISNUMBER(B16),ISNUMBER(C16),N($C$2)>0),ROUND(B16*$C$2-C16,2),"")
... D44: =IF(AND(ISNUMBER(B44),ISNUMBER(C44),N($C$2)>0),ROUND(B44*$C$2-C44,2),"")
A46: DAILY TOTALS
A47: Total AED Received | D47: =SUM(B5:B44) -> 0
A48: Total INR Given | D48: =SUM(C5:C44) -> 0
A49: Total Profit | D49: =SUMIF(D5:D44,">0") -> 0
A50: Total Loss | D50: =SUMIF(D5:D44,"<0") -> 0
A51: Net Profit/Loss | D51: =SUM(D5:D44) -> 0
A52: Number of Transactions | D52: =SUMPRODUCT(--((ISNUMBER(B5:B44)+ISNUMBER(C5:C44))>0)) -> 0

Sheet 04-Jan
A1: 🇦🇪 AED — UAE Dirham | C1: 🇮🇳 INR — Indian Rupee
A2: EXCHANGE RATE | B2: 1 AED = | D2: =IF(N(C2)>0,"","◄ enter today's rate") -> ◄ enter today's rate
A3: Yellow cell and blue figures are yours to type; everything else calculates automatically. Profit / Loss = AED Received × Rate − INR Given (100 AED at 25, ₹2,400 given → +₹100)
A4: Name | B4: AED Received | C4: INR Given | D4: Profit / Loss
D5: =IF(AND(ISNUMBER(B5),ISNUMBER(C5),N($C$2)>0),ROUND(B5*$C$2-C5,2),"")
D6: =IF(AND(ISNUMBER(B6),ISNUMBER(C6),N($C$2)>0),ROUND(B6*$C$2-C6,2),"")
D7: =IF(AND(ISNUMBER(B7),ISNUMBER(C7),N($C$2)>0),ROUND(B7*$C$2-C7,2),"")
D8: =IF(AND(ISNUMBER(B8),ISNUMBER(C8),N($C$2)>0),ROUND(B8*$C$2-C8,2),"")
D9: =IF(AND(ISNUMBER(B9),ISNUMBER(C9),N($C$2)>0),ROUND(B9*$C$2-C9,2),"")
D10: =IF(AND(ISNUMBER(B10),ISNUMBER(C10),N($C$2)>0),ROUND(B10*$C$2-C10,2),"")
D11: =IF(AND(ISNUMBER(B11),ISNUMBER(C11),N($C$2)>0),ROUND(B11*$C$2-C11,2),"")
D12: =IF(AND(ISNUMBER(B12),ISNUMBER(C12),N($C$2)>0),ROUND(B12*$C$2-C12,2),"")
D13: =IF(AND(ISNUMBER(B13),ISNUMBER(C13),N($C$2)>0),ROUND(B13*$C$2-C13,2),"")
D14: =IF(AND(ISNUMBER(B14),ISNUMBER(C14),N($C$2)>0),ROUND(B14*$C$2-C14,2),"")
D15: =IF(AND(ISNUMBER(B15),ISNUMBER(C15),N($C$2)>0),ROUND(B15*$C$2-C15,2),"")
D16: =IF(AND(ISNUMBER(B16),ISNUMBER(C16),N($C$2)>0),ROUND(B16*$C$2-C16,2),"")
... D44: =IF(AND(ISNUMBER(B44),ISNUMBER(C44),N($C$2)>0),ROUND(B44*$C$2-C44,2),"")
A46: DAILY TOTALS
A47: Total AED Received | D47: =SUM(B5:B44) -> 0
A48: Total INR Given | D48: =SUM(C5:C44) -> 0
A49: Total Profit | D49: =SUMIF(D5:D44,">0") -> 0
A50: Total Loss | D50: =SUMIF(D5:D44,"<0") -> 0
A51: Net Profit/Loss | D51: =SUM(D5:D44) -> 0
A52: Number of Transactions | D52: =SUMPRODUCT(--((ISNUMBER(B5:B44)+ISNUMBER(C5:C44))>0)) -> 0

Sheet 05-Jan
A1: 🇦🇪 AED — UAE Dirham | C1: 🇮🇳 INR — Indian Rupee
A2: EXCHANGE RATE | B2: 1 AED = | D2: =IF(N(C2)>0,"","◄ enter today's rate") -> ◄ enter today's rate
A3: Yellow cell and blue figures are yours to type; everything else calculates automatically. Profit / Loss = AED Received × Rate − INR Given (100 AED at 25, ₹2,400 given → +₹100)
A4: Name | B4: AED Received | C4: INR Given | D4: Profit / Loss
D5: =IF(AND(ISNUMBER(B5),ISNUMBER(C5),N($C$2)>0),ROUND(B5*$C$2-C5,2),"")
D6: =IF(AND(ISNUMBER(B6),ISNUMBER(C6),N($C$2)>0),ROUND(B6*$C$2-C6,2),"")
D7: =IF(AND(ISNUMBER(B7),ISNUMBER(C7),N($C$2)>0),ROUND(B7*$C$2-C7,2),"")
D8: =IF(AND(ISNUMBER(B8),ISNUMBER(C8),N($C$2)>0),ROUND(B8*$C$2-C8,2),"")
D9: =IF(AND(ISNUMBER(B9),ISNUMBER(C9),N($C$2)>0),ROUND(B9*$C$2-C9,2),"")
D10: =IF(AND(ISNUMBER(B10),ISNUMBER(C10),N($C$2)>0),ROUND(B10*$C$2-C10,2),"")
D11: =IF(AND(ISNUMBER(B11),ISNUMBER(C11),N($C$2)>0),ROUND(B11*$C$2-C11,2),"")
D12: =IF(AND(ISNUMBER(B12),ISNUMBER(C12),N($C$2)>0),ROUND(B12*$C$2-C12,2),"")
D13: =IF(AND(ISNUMBER(B13),ISNUMBER(C13),N($C$2)>0),ROUND(B13*$C$2-C13,2),"")
D14: =IF(AND(ISNUMBER(B14),ISNUMBER(C14),N($C$2)>0),ROUND(B14*$C$2-C14,2),"")
D15: =IF(AND(ISNUMBER(B15),ISNUMBER(C15),N($C$2)>0),ROUND(B15*$C$2-C15,2),"")
D16: =IF(AND(ISNUMBER(B16),ISNUMBER(C16),N($C$2)>0),ROUND(B16*$C$2-C16,2),"")
... D44: =IF(AND(ISNUMBER(B44),ISNUMBER(C44),N($C$2)>0),ROUND(B44*$C$2-C44,2),"")
A46: DAILY TOTALS
A47: Total AED Received | D47: =SUM(B5:B44) -> 0
A48: Total INR Given | D48: =SUM(C5:C44) -> 0
A49: Total Profit | D49: =SUMIF(D5:D44,">0") -> 0
A50: Total Loss | D50: =SUMIF(D5:D44,"<0") -> 0
A51: Net Profit/Loss | D51: =SUM(D5:D44) -> 0
A52: Number of Transactions | D52: =SUMPRODUCT(--((ISNUMBER(B5:B44)+ISNUMBER(C5:C44))>0)) -> 0

Sheet 06-Jan
A1: 🇦🇪 AED — UAE Dirham | C1: 🇮🇳 INR — Indian Rupee
A2: EXCHANGE RATE | B2: 1 AED = | D2: =IF(N(C2)>0,"","◄ enter today's rate") -> ◄ enter today's rate
A3: Yellow cell and blue figures are yours to type; everything else calculates automatically. Profit / Loss = AED Received × Rate − INR Given (100 AED at 25, ₹2,400 given → +₹100)
A4: Name | B4: AED Received | C4: INR Given | D4: Profit / Loss
D5: =IF(AND(ISNUMBER(B5),ISNUMBER(C5),N($C$2)>0),ROUND(B5*$C$2-C5,2),"")
D6: =IF(AND(ISNUMBER(B6),ISNUMBER(C6),N($C$2)>0),ROUND(B6*$C$2-C6,2),"")
D7: =IF(AND(ISNUMBER(B7),ISNUMBER(C7),N($C$2)>0),ROUND(B7*$C$2-C7,2),"")
D8: =IF(AND(ISNUMBER(B8),ISNUMBER(C8),N($C$2)>0),ROUND(B8*$C$2-C8,2),"")
D9: =IF(AND(ISNUMBER(B9),ISNUMBER(C9),N($C$2)>0),ROUND(B9*$C$2-C9,2),"")
D10: =IF(AND(ISNUMBER(B10),ISNUMBER(C10),N($C$2)>0),ROUND(B10*$C$2-C10,2),"")
D11: =IF(AND(ISNUMBER(B11),ISNUMBER(C11),N($C$2)>0),ROUND(B11*$C$2-C11,2),"")
D12: =IF(AND(ISNUMBER(B12),ISNUMBER(C12),N($C$2)>0),ROUND(B12*$C$2-C12,2),"")
D13: =IF(AND(ISNUMBER(B13),ISNUMBER(C13),N($C$2)>0),ROUND(B13*$C$2-C13,2),"")
D14: =IF(AND(ISNUMBER(B14),ISNUMBER(C14),N($C$2)>0),ROUND(B14*$C$2-C14,2),"")
D15: =IF(AND(ISNUMBER(B15),ISNUMBER(C15),N($C$2)>0),ROUND(B15*$C$2-C15,2),"")
D16: =IF(AND(ISNUMBER(B16),ISNUMBER(C16),N($C$2)>0),ROUND(B16*$C$2-C16,2),"")
... D44: =IF(AND(ISNUMBER(B44),ISNUMBER(C44),N($C$2)>0),ROUND(B44*$C$2-C44,2),"")
A46: DAILY TOTALS
A47: Total AED Received | D47: =SUM(B5:B44) -> 0
A48: Total INR Given | D48: =SUM(C5:C44) -> 0
A49: Total Profit | D49: =SUMIF(D5:D44,">0") -> 0
A50: Total Loss | D50: =SUMIF(D5:D44,"<0") -> 0
A51: Net Profit/Loss | D51: =SUM(D5:D44) -> 0
A52: Number of Transactions | D52: =SUMPRODUCT(--((ISNUMBER(B5:B44)+ISNUMBER(C5:C44))>0)) -> 0

Sheet 07-Jan
A1: 🇦🇪 AED — UAE Dirham | C1: 🇮🇳 INR — Indian Rupee
A2: EXCHANGE RATE | B2: 1 AED = | D2: =IF(N(C2)>0,"","◄ enter today's rate") -> ◄ enter today's rate
A3: Yellow cell and blue figures are yours to type; everything else calculates automatically. Profit / Loss = AED Received × Rate − INR Given (100 AED at 25, ₹2,400 given → +₹100)
A4: Name | B4: AED Received | C4: INR Given | D4: Profit / Loss
D5: =IF(AND(ISNUMBER(B5),ISNUMBER(C5),N($C$2)>0),ROUND(B5*$C$2-C5,2),"")
D6: =IF(AND(ISNUMBER(B6),ISNUMBER(C6),N($C$2)>0),ROUND(B6*$C$2-C6,2),"")
D7: =IF(AND(ISNUMBER(B7),ISNUMBER(C7),N($C$2)>0),ROUND(B7*$C$2-C7,2),"")
D8: =IF(AND(ISNUMBER(B8),ISNUMBER(C8),N($C$2)>0),ROUND(B8*$C$2-C8,2),"")
D9: =IF(AND(ISNUMBER(B9),ISNUMBER(C9),N($C$2)>0),ROUND(B9*$C$2-C9,2),"")
D10: =IF(AND(ISNUMBER(B10),ISNUMBER(C10),N($C$2)>0),ROUND(B10*$C$2-C10,2),"")
D11: =IF(AND(ISNUMBER(B11),ISNUMBER(C11),N($C$2)>0),ROUND(B11*$C$2-C11,2),"")
D12: =IF(AND(ISNUMBER(B12),ISNUMBER(C12),N($C$2)>0),ROUND(B12*$C$2-C12,2),"")
D13: =IF(AND(ISNUMBER(B13),ISNUMBER(C13),N($C$2)>0),ROUND(B13*$C$2-C13,2),"")
D14: =IF(AND(ISNUMBER(B14),ISNUMBER(C14),N($C$2)>0),ROUND(B14*$C$2-C14,2),"")
D15: =IF(AND(ISNUMBER(B15),ISNUMBER(C15),N($C$2)>0),ROUND(B15*$C$2-C15,2),"")
D16: =IF(AND(ISNUMBER(B16),ISNUMBER(C16),N($C$2)>0),ROUND(B16*$C$2-C16,2),"")
... D44: =IF(AND(ISNUMBER(B44),ISNUMBER(C44),N($C$2)>0),ROUND(B44*$C$2-C44,2),"")
A46: DAILY TOTALS
A47: Total AED Received | D47: =SUM(B5:B44) -> 0
A48: Total INR Given | D48: =SUM(C5:C44) -> 0
A49: Total Profit | D49: =SUMIF(D5:D44,">0") -> 0
A50: Total Loss | D50: =SUMIF(D5:D44,"<0") -> 0
A51: Net Profit/Loss | D51: =SUM(D5:D44) -> 0
A52: Number of Transactions | D52: =SUMPRODUCT(--((ISNUMBER(B5:B44)+ISNUMBER(C5:C44))>0)) -> 0

Sheet 08-Jan
A1: 🇦🇪 AED — UAE Dirham | C1: 🇮🇳 INR — Indian Rupee
A2: EXCHANGE RATE | B2: 1 AED = | D2: =IF(N(C2)>0,"","◄ enter today's rate") -> ◄ enter today's rate
A3: Yellow cell and blue figures are yours to type; everything else calculates automatically. Profit / Loss = AED Received × Rate − INR Given (100 AED at 25, ₹2,400 given → +₹100)
A4: Name | B4: AED Received | C4: INR Given | D4: Profit / Loss
D5: =IF(AND(ISNUMBER(B5),ISNUMBER(C5),N($C$2)>0),ROUND(B5*$C$2-C5,2),"")
D6: =IF(AND(ISNUMBER(B6),ISNUMBER(C6),N($C$2)>0),ROUND(B6*$C$2-C6,2),"")
D7: =IF(AND(ISNUMBER(B7),ISNUMBER(C7),N($C$2)>0),ROUND(B7*$C$2-C7,2),"")
D8: =IF(AND(ISNUMBER(B8),ISNUMBER(C8),N($C$2)>0),ROUND(B8*$C$2-C8,2),"")
D9: =IF(AND(ISNUMBER(B9),ISNUMBER(C9),N($C$2)>0),ROUND(B9*$C$2-C9,2),"")
D10: =IF(AND(ISNUMBER(B10),ISNUMBER(C10),N($C$2)>0),ROUND(B10*$C$2-C10,2),"")
D11: =IF(AND(ISNUMBER(B11),ISNUMBER(C11),N($C$2)>0),ROUND(B11*$C$2-C11,2),"")
D12: =IF(AND(ISNUMBER(B12),ISNUMBER(C12),N($C$2)>0),ROUND(B12*$C$2-C12,2),"")
D13: =IF(AND(ISNUMBER(B13),ISNUMBER(C13),N($C$2)>0),ROUND(B13*$C$2-C13,2),"")
D14: =IF(AND(ISNUMBER(B14),ISNUMBER(C14),N($C$2)>0),ROUND(B14*$C$2-C14,2),"")
D15: =IF(AND(ISNUMBER(B15),ISNUMBER(C15),N($C$2)>0),ROUND(B15*$C$2-C15,2),"")
D16: =IF(AND(ISNUMBER(B16),ISNUMBER(C16),N($C$2)>0),ROUND(B16*$C$2-C16,2),"")
... D44: =IF(AND(ISNUMBER(B44),ISNUMBER(C44),N($C$2)>0),ROUND(B44*$C$2-C44,2),"")
A46: DAILY TOTALS
A47: Total AED Received | D47: =SUM(B5:B44) -> 0
A48: Total INR Given | D48: =SUM(C5:C44) -> 0
A49: Total Profit | D49: =SUMIF(D5:D44,">0") -> 0
A50: Total Loss | D50: =SUMIF(D5:D44,"<0") -> 0
A51: Net Profit/Loss | D51: =SUM(D5:D44) -> 0
A52: Number of Transactions | D52: =SUMPRODUCT(--((ISNUMBER(B5:B44)+ISNUMBER(C5:C44))>0)) -> 0

Sheet 09-Jan
A1: 🇦🇪 AED — UAE Dirham | C1: 🇮🇳 INR — Indian Rupee
A2: EXCHANGE RATE | B2: 1 AED = | D2: =IF(N(C2)>0,"","◄ enter today's rate") -> ◄ enter today's rate
A3: Yellow cell and blue figures are yours to type; everything else calculates automatically. Profit / Loss = AED Received × Rate − INR Given (100 AED at 25, ₹2,400 given → +₹100)
A4: Name | B4: AED Received | C4: INR Given | D4: Profit / Loss
D5: =IF(AND(ISNUMBER(B5),ISNUMBER(C5),N($C$2)>0),ROUND(B5*$C$2-C5,2),"")
D6: =IF(AND(ISNUMBER(B6),ISNUMBER(C6),N($C$2)>0),ROUND(B6*$C$2-C6,2),"")
D7: =IF(AND(ISNUMBER(B7),ISNUMBER(C7),N($C$2)>0),ROUND(B7*$C$2-C7,2),"")
D8: =IF(AND(ISNUMBER(B8),ISNUMBER(C8),N($C$2)>0),ROUND(B8*$C$2-C8,2),"")
D9: =IF(AND(ISNUMBER(B9),ISNUMBER(C9),N($C$2)>0),ROUND(B9*$C$2-C9,2),"")
D10: =IF(AND(ISNUMBER(B10),ISNUMBER(C10),N($C$2)>0),ROUND(B10*$C$2-C10,2),"")
D11: =IF(AND(ISNUMBER(B11),ISNUMBER(C11),N($C$2)>0),ROUND(B11*$C$2-C11,2),"")
D12: =IF(AND(ISNUMBER(B12),ISNUMBER(C12),N($C$2)>0),ROUND(B12*$C$2-C12,2),"")
D13: =IF(AND(ISNUMBER(B13),ISNUMBER(C13),N($C$2)>0),ROUND(B13*$C$2-C13,2),"")
D14: =IF(AND(ISNUMBER(B14),ISNUMBER(C14),N($C$2)>0),ROUND(B14*$C$2-C14,2),"")
D15: =IF(AND(ISNUMBER(B15),ISNUMBER(C15),N($C$2)>0),ROUND(B15*$C$2-C15,2),"")
D16: =IF(AND(ISNUMBER(B16),ISNUMBER(C16),N($C$2)>0),ROUND(B16*$C$2-C16,2),"")
... D44: =IF(AND(ISNUMBER(B44),ISNUMBER(C44),N($C$2)>0),ROUND(B44*$C$2-C44,2),"")
A46: DAILY TOTALS
A47: Total AED Received | D47: =SUM(B5:B44) -> 0
A48: Total INR Given | D48: =SUM(C5:C44) -> 0
A49: Total Profit | D49: =SUMIF(D5:D44,">0") -> 0
A50: Total Loss | D50: =SUMIF(D5:D44,"<0") -> 0
A51: Net Profit/Loss | D51: =SUM(D5:D44) -> 0
A52: Number of Transactions | D52: =SUMPRODUCT(--((ISNUMBER(B5:B44)+ISNUMBER(C5:C44))>0)) -> 0

Sheet 10-Jan
A1: 🇦🇪 AED — UAE Dirham | C1: 🇮🇳 INR — Indian Rupee
A2: EXCHANGE RATE | B2: 1 AED = | D2: =IF(N(C2)>0,"","◄ enter today's rate") -> ◄ enter today's rate
A3: Yellow cell and blue figures are yours to type; everything else calculates automatically. Profit / Loss = AED Received × Rate − INR Given (100 AED at 25, ₹2,400 given → +₹100)
A4: Name | B4: AED Received | C4: INR Given | D4: Profit / Loss
D5: =IF(AND(ISNUMBER(B5),ISNUMBER(C5),N($C$2)>0),ROUND(B5*$C$2-C5,2),"")
D6: =IF(AND(ISNUMBER(B6),ISNUMBER(C6),N($C$2)>0),ROUND(B6*$C$2-C6,2),"")
D7: =IF(AND(ISNUMBER(B7),ISNUMBER(C7),N($C$2)>0),ROUND(B7*$C$2-C7,2),"")
D8: =IF(AND(ISNUMBER(B8),ISNUMBER(C8),N($C$2)>0),ROUND(B8*$C$2-C8,2),"")
D9: =IF(AND(ISNUMBER(B9),ISNUMBER(C9),N($C$2)>0),ROUND(B9*$C$2-C9,2),"")
D10: =IF(AND(ISNUMBER(B10),ISNUMBER(C10),N($C$2)>0),ROUND(B10*$C$2-C10,2),"")
D11: =IF(AND(ISNUMBER(B11),ISNUMBER(C11),N($C$2)>0),ROUND(B11*$C$2-C11,2),"")
D12: =IF(AND(ISNUMBER(B12),ISNUMBER(C12),N($C$2)>0),ROUND(B12*$C$2-C12,2),"")
D13: =IF(AND(ISNUMBER(B13),ISNUMBER(C13),N($C$2)>0),ROUND(B13*$C$2-C13,2),"")
D14: =IF(AND(ISNUMBER(B14),ISNUMBER(C14),N($C$2)>0),ROUND(B14*$C$2-C14,2),"")
D15: =IF(AND(ISNUMBER(B15),ISNUMBER(C15),N($C$2)>0),ROUND(B15*$C$2-C15,2),"")
D16: =IF(AND(ISNUMBER(B16),ISNUMBER(C16),N($C$2)>0),ROUND(B16*$C$2-C16,2),"")
... D44: =IF(AND(ISNUMBER(B44),ISNUMBER(C44),N($C$2)>0),ROUND(B44*$C$2-C44,2),"")
A46: DAILY TOTALS
A47: Total AED Received | D47: =SUM(B5:B44) -> 0
A48: Total INR Given | D48: =SUM(C5:C44) -> 0
A49: Total Profit | D49: =SUMIF(D5:D44,">0") -> 0
A50: Total Loss | D50: =SUMIF(D5:D44,"<0") -> 0
A51: Net Profit/Loss | D51: =SUM(D5:D44) -> 0
A52: Number of Transactions | D52: =SUMPRODUCT(--((ISNUMBER(B5:B44)+ISNUMBER(C5:C44))>0)) -> 0

Sheet 11-Jan
A1: 🇦🇪 AED — UAE Dirham | C1: 🇮🇳 INR — Indian Rupee
A2: EXCHANGE RATE | B2: 1 AED = | D2: =IF(N(C2)>0,"","◄ enter today's rate") -> ◄ enter today's rate
A3: Yellow cell and blue figures are yours to type; everything else calculates automatically. Profit / Loss = AED Received × Rate − INR Given (100 AED at 25, ₹2,400 given → +₹100)
A4: Name | B4: AED Received | C4: INR Given | D4: Profit / Loss
D5: =IF(AND(ISNUMBER(B5),ISNUMBER(C5),N($C$2)>0),ROUND(B5*$C$2-C5,2),"")
D6: =IF(AND(ISNUMBER(B6),ISNUMBER(C6),N($C$2)>0),ROUND(B6*$C$2-C6,2),"")
D7: =IF(AND(ISNUMBER(B7),ISNUMBER(C7),N($C$2)>0),ROUND(B7*$C$2-C7,2),"")
D8: =IF(AND(ISNUMBER(B8),ISNUMBER(C8),N($C$2)>0),ROUND(B8*$C$2-C8,2),"")
D9: =IF(AND(ISNUMBER(B9),ISNUMBER(C9),N($C$2)>0),ROUND(B9*$C$2-C9,2),"")
D10: =IF(AND(ISNUMBER(B10),ISNUMBER(C10),N($C$2)>0),ROUND(B10*$C$2-C10,2),"")
D11: =IF(AND(ISNUMBER(B11),ISNUMBER(C11),N($C$2)>0),ROUND(B11*$C$2-C11,2),"")
D12: =IF(AND(ISNUMBER(B12),ISNUMBER(C12),N($C$2)>0),ROUND(B12*$C$2-C12,2),"")
D13: =IF(AND(ISNUMBER(B13),ISNUMBER(C13),N($C$2)>0),ROUND(B13*$C$2-C13,2),"")
D14: =IF(AND(ISNUMBER(B14),ISNUMBER(C14),N($C$2)>0),ROUND(B14*$C$2-C14,2),"")
D15: =IF(AND(ISNUMBER(B15),ISNUMBER(C15),N($C$2)>0),ROUND(B15*$C$2-C15,2),"")
D16: =IF(AND(ISNUMBER(B16),ISNUMBER(C16),N($C$2)>0),ROUND(B16*$C$2-C16,2),"")
... D44: =IF(AND(ISNUMBER(B44),ISNUMBER(C44),N($C$2)>0),ROUND(B44*$C$2-C44,2),"")
A46: DAILY TOTALS
A47: Total AED Received | D47: =SUM(B5:B44) -> 0
A48: Total INR Given | D48: =SUM(C5:C44) -> 0
A49: Total Profit | D49: =SUMIF(D5:D44,">0") -> 0
A50: Total Loss | D50: =SUMIF(D5:D44,"<0") -> 0
A51: Net Profit/Loss | D51: =SUM(D5:D44) -> 0
A52: Number of Transactions | D52: =SUMPRODUCT(--((ISNUMBER(B5:B44)+ISNUMBER(C5:C44))>0)) -> 0

Sheet 12-Jan
A1: 🇦🇪 AED — UAE Dirham | C1: 🇮🇳 INR — Indian Rupee
A2: EXCHANGE RATE | B2: 1 AED = | D2: =IF(N(C2)>0,"","◄ enter today's rate") -> ◄ enter today's rate
A3: Yellow cell and blue figures are yours to type; everything else calculates automatically. Profit / Loss = AED Received × Rate − INR Given (100 AED at 25, ₹2,400 given → +₹100)
A4: Name | B4: AED Received | C4: INR Given | D4: Profit / Loss
D5: =IF(AND(ISNUMBER(B5),ISNUMBER(C5),N($C$2)>0),ROUND(B5*$C$2-C5,2),"")
D6: =IF(AND(ISNUMBER(B6),ISNUMBER(C6),N($C$2)>0),ROUND(B6*$C$2-C6,2),"")
D7: =IF(AND(ISNUMBER(B7),ISNUMBER(C7),N($C$2)>0),ROUND(B7*$C$2-C7,2),"")
D8: =IF(AND(ISNUMBER(B8),ISNUMBER(C8),N($C$2)>0),ROUND(B8*$C$2-C8,2),"")
D9: =IF(AND(ISNUMBER(B9),ISNUMBER(C9),N($C$2)>0),ROUND(B9*$C$2-C9,2),"")
D10: =IF(AND(ISNUMBER(B10),ISNUMBER(C10),N($C$2)>0),ROUND(B10*$C$2-C10,2),"")
D11: =IF(AND(ISNUMBER(B11),ISNUMBER(C11),N($C$2)>0),ROUND(B11*$C$2-C11,2),"")
D12: =IF(AND(ISNUMBER(B12),ISNUMBER(C12),N($C$2)>0),ROUND(B12*$C$2-C12,2),"")
D13: =IF(AND(ISNUMBER(B13),ISNUMBER(C13),N($C$2)>0),ROUND(B13*$C$2-C13,2),"")
D14: =IF(AND(ISNUMBER(B14),ISNUMBER(C14),N($C$2)>0),ROUND(B14*$C$2-C14,2),"")
D15: =IF(AND(ISNUMBER(B15),ISNUMBER(C15),N($C$2)>0),ROUND(B15*$C$2-C15,2),"")
D16: =IF(AND(ISNUMBER(B16),ISNUMBER(C16),N($C$2)>0),ROUND(B16*$C$2-C16,2),"")
... D44: =IF(AND(ISNUMBER(B44),ISNUMBER(C44),N($C$2)>0),ROUND(B44*$C$2-C44,2),"")
A46: DAILY TOTALS
A47: Total AED Received | D47: =SUM(B5:B44) -> 0
A48: Total INR Given | D48: =SUM(C5:C44) -> 0
A49: Total Profit | D49: =SUMIF(D5:D44,">0") -> 0
A50: Total Loss | D50: =SUMIF(D5:D44,"<0") -> 0
A51: Net Profit/Loss | D51: =SUM(D5:D44) -> 0
A52: Number of Transactions | D52: =SUMPRODUCT(--((ISNUMBER(B5:B44)+ISNUMBER(C5:C44))>0)) -> 0

Sheet 13-Jan
A1: 🇦🇪 AED — UAE Dirham | C1: 🇮🇳 INR — Indian Rupee
A2: EXCHANGE RATE | B2: 1 AED = | D2: =IF(N(C2)>0,"","◄ enter today's rate") -> ◄ enter today's rate
A3: Yellow cell and blue figures are yours to type; everything else calculates automatically. Profit / Loss = AED Received × Rate − INR Given (100 AED at 25, ₹2,400 given → +₹100)
A4: Name | B4: AED Received | C4: INR Given | D4: Profit / Loss
D5: =IF(AND(ISNUMBER(B5),ISNUMBER(C5),N($C$2)>0),ROUND(B5*$C$2-C5,2),"")
D6: =IF(AND(ISNUMBER(B6),ISNUMBER(C6),N($C$2)>0),ROUND(B6*$C$2-C6,2),"")
D7: =IF(AND(ISNUMBER(B7),ISNUMBER(C7),N($C$2)>0),ROUND(B7*$C$2-C7,2),"")
D8: =IF(AND(ISNUMBER(B8),ISNUMBER(C8),N($C$2)>0),ROUND(B8*$C$2-C8,2),"")
D9: =IF(AND(ISNUMBER(B9),ISNUMBER(C9),N($C$2)>0),ROUND(B9*$C$2-C9,2),"")
D10: =IF(AND(ISNUMBER(B10),ISNUMBER(C10),N($C$2)>0),ROUND(B10*$C$2-C10,2),"")
D11: =IF(AND(ISNUMBER(B11),ISNUMBER(C11),N($C$2)>0),ROUND(B11*$C$2-C11,2),"")
D12: =IF(AND(ISNUMBER(B12),ISNUMBER(C12),N($C$2)>0),ROUND(B12*$C$2-C12,2),"")
D13: =IF(AND(ISNUMBER(B13),ISNUMBER(C13),N($C$2)>0),ROUND(B13*$C$2-C13,2),"")
D14: =IF(AND(ISNUMBER(B14),ISNUMBER(C14),N($C$2)>0),ROUND(B14*$C$2-C14,2),"")
D15: =IF(AND(ISNUMBER(B15),ISNUMBER(C15),N($C$2)>0),ROUND(B15*$C$2-C15,2),"")
D16: =IF(AND(ISNUMBER(B16),ISNUMBER(C16),N($C$2)>0),ROUND(B16*$C$2-C16,2),"")
... D44: =IF(AND(ISNUMBER(B44),ISNUMBER(C44),N($C$2)>0),ROUND(B44*$C$2-C44,2),"")
A46: DAILY TOTALS
A47: Total AED Received | D47: =SUM(B5:B44) -> 0
A48: Total INR Given | D48: =SUM(C5:C44) -> 0
A49: Total Profit | D49: =SUMIF(D5:D44,">0") -> 0
A50: Total Loss | D50: =SUMIF(D5:D44,"<0") -> 0
A51: Net Profit/Loss | D51: =SUM(D5:D44) -> 0
A52: Number of Transactions | D52: =SUMPRODUCT(--((ISNUMBER(B5:B44)+ISNUMBER(C5:C44))>0)) -> 0

Sheet 14-Jan
A1: 🇦🇪 AED — UAE Dirham | C1: 🇮🇳 INR — Indian Rupee
A2: EXCHANGE RATE | B2: 1 AED = | D2: =IF(N(C2)>0,"","◄ enter today's rate") -> ◄ enter today's rate
A3: Yellow cell and blue figures are yours to type; everything else calculates automatically. Profit / Loss = AED Received × Rate − INR Given (100 AED at 25, ₹2,400 given → +₹100)
A4: Name | B4: AED Received | C4: INR Given | D4: Profit / Loss
D5: =IF(AND(ISNUMBER(B5),ISNUMBER(C5),N($C$2)>0),ROUND(B5*$C$2-C5,2),"")
D6: =IF(AND(ISNUMBER(B6),ISNUMBER(C6),N($C$2)>0),ROUND(B6*$C$2-C6,2),"")
D7: =IF(AND(ISNUMBER(B7),ISNUMBER(C7),N($C$2)>0),ROUND(B7*$C$2-C7,2),"")
D8: =IF(AND(ISNUMBER(B8),ISNUMBER(C8),N($C$2)>0),ROUND(B8*$C$2-C8,2),"")
D9: =IF(AND(ISNUMBER(B9),ISNUMBER(C9),N($C$2)>0),ROUND(B9*$C$2-C9,2),"")
D10: =IF(AND(ISNUMBER(B10),ISNUMBER(C10),N($C$2)>0),ROUND(B10*$C$2-C10,2),"")
D11: =IF(AND(ISNUMBER(B11),ISNUMBER(C11),N($C$2)>0),ROUND(B11*$C$2-C11,2),"")
D12: =IF(AND(ISNUMBER(B12),ISNUMBER(C12),N($C$2)>0),ROUND(B12*$C$2-C12,2),"")
D13: =IF(AND(ISNUMBER(B13),ISNUMBER(C13),N($C$2)>0),ROUND(B13*$C$2-C13,2),"")
D14: =IF(AND(ISNUMBER(B14),ISNUMBER(C14),N($C$2)>0),ROUND(B14*$C$2-C14,2),"")
D15: =IF(AND(ISNUMBER(B15),ISNUMBER(C15),N($C$2)>0),ROUND(B15*$C$2-C15,2),"")
D16: =IF(AND(ISNUMBER(B16),ISNUMBER(C16),N($C$2)>0),ROUND(B16*$C$2-C16,2),"")
... D44: =IF(AND(ISNUMBER(B44),ISNUMBER(C44),N($C$2)>0),ROUND(B44*$C$2-C44,2),"")
A46: DAILY TOTALS
A47: Total AED Received | D47: =SUM(B5:B44) -> 0
A48: Total INR Given | D48: =SUM(C5:C44) -> 0
A49: Total Profit | D49: =SUMIF(D5:D44,">0") -> 0
A50: Total Loss | D50: =SUMIF(D5:D44,"<0") -> 0
A51: Net Profit/Loss | D51: =SUM(D5:D44) -> 0
A52: Number of Transactions | D52: =SUMPRODUCT(--((ISNUMBER(B5:B44)+ISNUMBER(C5:C44))>0)) -> 0

Sheet 15-Jan
A1: 🇦🇪 AED — UAE Dirham | C1: 🇮🇳 INR — Indian Rupee
A2: EXCHANGE RATE | B2: 1 AED = | D2: =IF(N(C2)>0,"","◄ enter today's rate") -> ◄ enter today's rate
A3: Yellow cell and blue figures are yours to type; everything else calculates automatically. Profit / Loss = AED Received × Rate − INR Given (100 AED at 25, ₹2,400 given → +₹100)
A4: Name | B4: AED Received | C4: INR Given | D4: Profit / Loss
D5: =IF(AND(ISNUMBER(B5),ISNUMBER(C5),N($C$2)>0),ROUND(B5*$C$2-C5,2),"")
D6: =IF(AND(ISNUMBER(B6),ISNUMBER(C6),N($C$2)>0),ROUND(B6*$C$2-C6,2),"")
D7: =IF(AND(ISNUMBER(B7),ISNUMBER(C7),N($C$2)>0),ROUND(B7*$C$2-C7,2),"")
D8: =IF(AND(ISNUMBER(B8),ISNUMBER(C8),N($C$2)>0),ROUND(B8*$C$2-C8,2),"")
D9: =IF(AND(ISNUMBER(B9),ISNUMBER(C9),N($C$2)>0),ROUND(B9*$C$2-C9,2),"")
D10: =IF(AND(ISNUMBER(B10),ISNUMBER(C10),N($C$2)>0),ROUND(B10*$C$2-C10,2),"")
D11: =IF(AND(ISNUMBER(B11),ISNUMBER(C11),N($C$2)>0),ROUND(B11*$C$2-C11,2),"")
D12: =IF(AND(ISNUMBER(B12),ISNUMBER(C12),N($C$2)>0),ROUND(B12*$C$2-C12,2),"")
D13: =IF(AND(ISNUMBER(B13),ISNUMBER(C13),N($C$2)>0),ROUND(B13*$C$2-C13,2),"")
D14: =IF(AND(ISNUMBER(B14),ISNUMBER(C14),N($C$2)>0),ROUND(B14*$C$2-C14,2),"")
D15: =IF(AND(ISNUMBER(B15),ISNUMBER(C15),N($C$2)>0),ROUND(B15*$C$2-C15,2),"")
D16: =IF(AND(ISNUMBER(B16),ISNUMBER(C16),N($C$2)>0),ROUND(B16*$C$2-C16,2),"")
... D44: =IF(AND(ISNUMBER(B44),ISNUMBER(C44),N($C$2)>0),ROUND(B44*$C$2-C44,2),"")
A46: DAILY TOTALS
A47: Total AED Received | D47: =SUM(B5:B44) -> 0
A48: Total INR Given | D48: =SUM(C5:C44) -> 0
A49: Total Profit | D49: =SUMIF(D5:D44,">0") -> 0
A50: Total Loss | D50: =SUMIF(D5:D44,"<0") -> 0
A51: Net Profit/Loss | D51: =SUM(D5:D44) -> 0
A52: Number of Transactions | D52: =SUMPRODUCT(--((ISNUMBER(B5:B44)+ISNUMBER(C5:C44))>0)) -> 0

Sheet 16-Jan
A1: 🇦🇪 AED — UAE Dirham | C1: 🇮🇳 INR — Indian Rupee
A2: EXCHANGE RATE | B2: 1 AED = | D2: =IF(N(C2)>0,"","◄ enter today's rate") -> ◄ enter today's rate
A3: Yellow cell and blue figures are yours to type; everything else calculates automatically. Profit / Loss = AED Received × Rate − INR Given (100 AED at 25, ₹2,400 given → +₹100)
A4: Name | B4: AED Received | C4: INR Given | D4: Profit / Loss
D5: =IF(AND(ISNUMBER(B5),ISNUMBER(C5),N($C$2)>0),ROUND(B5*$C$2-C5,2),"")
D6: =IF(AND(ISNUMBER(B6),ISNUMBER(C6),N($C$2)>0),ROUND(B6*$C$2-C6,2),"")
D7: =IF(AND(ISNUMBER(B7),ISNUMBER(C7),N($C$2)>0),ROUND(B7*$C$2-C7,2),"")
D8: =IF(AND(ISNUMBER(B8),ISNUMBER(C8),N($C$2)>0),ROUND(B8*$C$2-C8,2),"")
D9: =IF(AND(ISNUMBER(B9),ISNUMBER(C9),N($C$2)>0),ROUND(B9*$C$2-C9,2),"")
D10: =IF(AND(ISNUMBER(B10),ISNUMBER(C10),N($C$2)>0),ROUND(B10*$C$2-C10,2),"")
D11: =IF(AND(ISNUMBER(B11),ISNUMBER(C11),N($C$2)>0),ROUND(B11*$C$2-C11,2),"")
D12: =IF(AND(ISNUMBER(B12),ISNUMBER(C12),N($C$2)>0),ROUND(B12*$C$2-C12,2),"")
D13: =IF(AND(ISNUMBER(B13),ISNUMBER(C13),N($C$2)>0),ROUND(B13*$C$2-C13,2),"")
D14: =IF(AND(ISNUMBER(B14),ISNUMBER(C14),N($C$2)>0),ROUND(B14*$C$2-C14,2),"")
D15: =IF(AND(ISNUMBER(B15),ISNUMBER(C15),N($C$2)>0),ROUND(B15*$C$2-C15,2),"")
D16: =IF(AND(ISNUMBER(B16),ISNUMBER(C16),N($C$2)>0),ROUND(B16*$C$2-C16,2),"")
... D44: =IF(AND(ISNUMBER(B44),ISNUMBER(C44),N($C$2)>0),ROUND(B44*$C$2-C44,2),"")
A46: DAILY TOTALS
A47: Total AED Received | D47: =SUM(B5:B44) -> 0
A48: Total INR Given | D48: =SUM(C5:C44) -> 0
A49: Total Profit | D49: =SUMIF(D5:D44,">0") -> 0
A50: Total Loss | D50: =SUMIF(D5:D44,"<0") -> 0
A51: Net Profit/Loss | D51: =SUM(D5:D44) -> 0
A52: Number of Transactions | D52: =SUMPRODUCT(--((ISNUMBER(B5:B44)+ISNUMBER(C5:C44))>0)) -> 0

Sheet 17-Jan
A1: 🇦🇪 AED — UAE Dirham | C1: 🇮🇳 INR — Indian Rupee
A2: EXCHANGE RATE | B2: 1 AED = | D2: =IF(N(C2)>0,"","◄ enter today's rate") -> ◄ enter today's rate
A3: Yellow cell and blue figures are yours to type; everything else calculates automatically. Profit / Loss = AED Received × Rate − INR Given (100 AED at 25, ₹2,400 given → +₹100)
A4: Name | B4: AED Received | C4: INR Given | D4: Profit / Loss
D5: =IF(AND(ISNUMBER(B5),ISNUMBER(C5),N($C$2)>0),ROUND(B5*$C$2-C5,2),"")
D6: =IF(AND(ISNUMBER(B6),ISNUMBER(C6),N($C$2)>0),ROUND(B6*$C$2-C6,2),"")
D7: =IF(AND(ISNUMBER(B7),ISNUMBER(C7),N($C$2)>0),ROUND(B7*$C$2-C7,2),"")
D8: =IF(AND(ISNUMBER(B8),ISNUMBER(C8),N($C$2)>0),ROUND(B8*$C$2-C8,2),"")
D9: =IF(AND(ISNUMBER(B9),ISNUMBER(C9),N($C$2)>0),ROUND(B9*$C$2-C9,2),"")
D10: =IF(AND(ISNUMBER(B10),ISNUMBER(C10),N($C$2)>0),ROUND(B10*$C$2-C10,2),"")
D11: =IF(AND(ISNUMBER(B11),ISNUMBER(C11),N($C$2)>0),ROUND(B11*$C$2-C11,2),"")
D12: =IF(AND(ISNUMBER(B12),ISNUMBER(C12),N($C$2)>0),ROUND(B12*$C$2-C12,2),"")
D13: =IF(AND(ISNUMBER(B13),ISNUMBER(C13),N($C$2)>0),ROUND(B13*$C$2-C13,2),"")
D14: =IF(AND(ISNUMBER(B14),ISNUMBER(C14),N($C$2)>0),ROUND(B14*$C$2-C14,2),"")
D15: =IF(AND(ISNUMBER(B15),ISNUMBER(C15),N($C$2)>0),ROUND(B15*$C$2-C15,2),"")
D16: =IF(AND(ISNUMBER(B16),ISNUMBER(C16),N($C$2)>0),ROUND(B16*$C$2-C16,2),"")
... D44: =IF(AND(ISNUMBER(B44),ISNUMBER(C44),N($C$2)>0),ROUND(B44*$C$2-C44,2),"")
A46: DAILY TOTALS
A47: Total AED Received | D47: =SUM(B5:B44) -> 0
A48: Total INR Given | D48: =SUM(C5:C44) -> 0
A49: Total Profit | D49: =SUMIF(D5:D44,">0") -> 0
A50: Total Loss | D50: =SUMIF(D5:D44,"<0") -> 0
A51: Net Profit/Loss | D51: =SUM(D5:D44) -> 0
A52: Number of Transactions | D52: =SUMPRODUCT(--((ISNUMBER(B5:B44)+ISNUMBER(C5:C44))>0)) -> 0

Sheet 18-Jan
A1: 🇦🇪 AED — UAE Dirham | C1: 🇮🇳 INR — Indian Rupee
A2: EXCHANGE RATE | B2: 1 AED = | D2: =IF(N(C2)>0,"","◄ enter today's rate") -> ◄ enter today's rate
A3: Yellow cell and blue figures are yours to type; everything else calculates automatically. Profit / Loss = AED Received × Rate − INR Given (100 AED at 25, ₹2,400 given → +₹100)
A4: Name | B4: AED Received | C4: INR Given | D4: Profit / Loss
D5: =IF(AND(ISNUMBER(B5),ISNUMBER(C5),N($C$2)>0),ROUND(B5*$C$2-C5,2),"")
D6: =IF(AND(ISNUMBER(B6),ISNUMBER(C6),N($C$2)>0),ROUND(B6*$C$2-C6,2),"")
D7: =IF(AND(ISNUMBER(B7),ISNUMBER(C7),N($C$2)>0),ROUND(B7*$C$2-C7,2),"")
D8: =IF(AND(ISNUMBER(B8),ISNUMBER(C8),N($C$2)>0),ROUND(B8*$C$2-C8,2),"")
D9: =IF(AND(ISNUMBER(B9),ISNUMBER(C9),N($C$2)>0),ROUND(B9*$C$2-C9,2),"")
D10: =IF(AND(ISNUMBER(B10),ISNUMBER(C10),N($C$2)>0),ROUND(B10*$C$2-C10,2),"")
D11: =IF(AND(ISNUMBER(B11),ISNUMBER(C11),N($C$2)>0),ROUND(B11*$C$2-C11,2),"")
D12: =IF(AND(ISNUMBER(B12),ISNUMBER(C12),N($C$2)>0),ROUND(B12*$C$2-C12,2),"")
D13: =IF(AND(ISNUMBER(B13),ISNUMBER(C13),N($C$2)>0),ROUND(B13*$C$2-C13,2),"")
D14: =IF(AND(ISNUMBER(B14),ISNUMBER(C14),N($C$2)>0),ROUND(B14*$C$2-C14,2),"")
D15: =IF(AND(ISNUMBER(B15),ISNUMBER(C15),N($C$2)>0),ROUND(B15*$C$2-C15,2),"")
D16: =IF(AND(ISNUMBER(B16),ISNUMBER(C16),N($C$2)>0),ROUND(B16*$C$2-C16,2),"")
... D44: =IF(AND(ISNUMBER(B44),ISNUMBER(C44),N($C$2)>0),ROUND(B44*$C$2-C44,2),"")
A46: DAILY TOTALS
A47: Total AED Received | D47: =SUM(B5:B44) -> 0
A48: Total INR Given | D48: =SUM(C5:C44) -> 0
A49: Total Profit | D49: =SUMIF(D5:D44,">0") -> 0
A50: Total Loss | D50: =SUMIF(D5:D44,"<0") -> 0
A51: Net Profit/Loss | D51: =SUM(D5:D44) -> 0
A52: Number of Transactions | D52: =SUMPRODUCT(--((ISNUMBER(B5:B44)+ISNUMBER(C5:C44))>0)) -> 0

Sheet 19-Jan
A1: 🇦🇪 AED — UAE Dirham | C1: 🇮🇳 INR — Indian Rupee
A2: EXCHANGE RATE | B2: 1 AED = | D2: =IF(N(C2)>0,"","◄ enter today's rate") -> ◄ enter today's rate
A3: Yellow cell and blue figures are yours to type; everything else calculates automatically. Profit / Loss = AED Received × Rate − INR Given (100 AED at 25, ₹2,400 given → +₹100)
A4: Name | B4: AED Received | C4: INR Given | D4: Profit / Loss
D5: =IF(AND(ISNUMBER(B5),ISNUMBER(C5),N($C$2)>0),ROUND(B5*$C$2-C5,2),"")
D6: =IF(AND(ISNUMBER(B6),ISNUMBER(C6),N($C$2)>0),ROUND(B6*$C$2-C6,2),"")
D7: =IF(AND(ISNUMBER(B7),ISNUMBER(C7),N($C$2)>0),ROUND(B7*$C$2-C7,2),"")
D8: =IF(AND(ISNUMBER(B8),ISNUMBER(C8),N($C$2)>0),ROUND(B8*$C$2-C8,2),"")
D9: =IF(AND(ISNUMBER(B9),ISNUMBER(C9),N($C$2)>0),ROUND(B9*$C$2-C9,2),"")
D10: =IF(AND(ISNUMBER(B10),ISNUMBER(C10),N($C$2)>0),ROUND(B10*$C$2-C10,2),"")
D11: =IF(AND(ISNUMBER(B11),ISNUMBER(C11),N($C$2)>0),ROUND(B11*$C$2-C11,2),"")
D12: =IF(AND(ISNUMBER(B12),ISNUMBER(C12),N($C$2)>0),ROUND(B12*$C$2-C12,2),"")
D13: =IF(AND(ISNUMBER(B13),ISNUMBER(C13),N($C$2)>0),ROUND(B13*$C$2-C13,2),"")
D14: =IF(AND(ISNUMBER(B14),ISNUMBER(C14),N($C$2)>0),ROUND(B14*$C$2-C14,2),"")
D15: =IF(AND(ISNUMBER(B15),ISNUMBER(C15),N($C$2)>0),ROUND(B15*$C$2-C15,2),"")
D16: =IF(AND(ISNUMBER(B16),ISNUMBER(C16),N($C$2)>0),ROUND(B16*$C$2-C16,2),"")
... D44: =IF(AND(ISNUMBER(B44),ISNUMBER(C44),N($C$2)>0),ROUND(B44*$C$2-C44,2),"")
A46: DAILY TOTALS
A47: Total AED Received | D47: =SUM(B5:B44) -> 0
A48: Total INR Given | D48: =SUM(C5:C44) -> 0
A49: Total Profit | D49: =SUMIF(D5:D44,">0") -> 0
A50: Total Loss | D50: =SUMIF(D5:D44,"<0") -> 0
A51: Net Profit/Loss | D51: =SUM(D5:D44) -> 0
A52: Number of Transactions | D52: =SUMPRODUCT(--((ISNUMBER(B5:B44)+ISNUMBER(C5:C44))>0)) -> 0

Sheet 20-Jan
A1: 🇦🇪 AED — UAE Dirham | C1: 🇮🇳 INR — Indian Rupee
A2: EXCHANGE RATE | B2: 1 AED = | D2: =IF(N(C2)>0,"","◄ enter today's rate") -> ◄ enter today's rate
A3: Yellow cell and blue figures are yours to type; everything else calculates automatically. Profit / Loss = AED Received × Rate − INR Given (100 AED at 25, ₹2,400 given → +₹100)
A4: Name | B4: AED Received | C4: INR Given | D4: Profit / Loss
D5: =IF(AND(ISNUMBER(B5),ISNUMBER(C5),N($C$2)>0),ROUND(B5*$C$2-C5,2),"")
D6: =IF(AND(ISNUMBER(B6),ISNUMBER(C6),N($C$2)>0),ROUND(B6*$C$2-C6,2),"")
D7: =IF(AND(ISNUMBER(B7),ISNUMBER(C7),N($C$2)>0),ROUND(B7*$C$2-C7,2),"")
D8: =IF(AND(ISNUMBER(B8),ISNUMBER(C8),N($C$2)>0),ROUND(B8*$C$2-C8,2),"")
D9: =IF(AND(ISNUMBER(B9),ISNUMBER(C9),N($C$2)>0),ROUND(B9*$C$2-C9,2),"")
D10: =IF(AND(ISNUMBER(B10),ISNUMBER(C10),N($C$2)>0),ROUND(B10*$C$2-C10,2),"")
D11: =IF(AND(ISNUMBER(B11),ISNUMBER(C11),N($C$2)>0),ROUND(B11*$C$2-C11,2),"")
D12: =IF(AND(ISNUMBER(B12),ISNUMBER(C12),N($C$2)>0),ROUND(B12*$C$2-C12,2),"")
D13: =IF(AND(ISNUMBER(B13),ISNUMBER(C13),N($C$2)>0),ROUND(B13*$C$2-C13,2),"")
D14: =IF(AND(ISNUMBER(B14),ISNUMBER(C14),N($C$2)>0),ROUND(B14*$C$2-C14,2),"")
D15: =IF(AND(ISNUMBER(B15),ISNUMBER(C15),N($C$2)>0),ROUND(B15*$C$2-C15,2),"")
D16: =IF(AND(ISNUMBER(B16),ISNUMBER(C16),N($C$2)>0),ROUND(B16*$C$2-C16,2),"")
... D44: =IF(AND(ISNUMBER(B44),ISNUMBER(C44),N($C$2)>0),ROUND(B44*$C$2-C44,2),"")
A46: DAILY TOTALS
A47: Total AED Received | D47: =SUM(B5:B44) -> 0
A48: Total INR Given | D48: =SUM(C5:C44) -> 0
A49: Total Profit | D49: =SUMIF(D5:D44,">0") -> 0
A50: Total Loss | D50: =SUMIF(D5:D44,"<0") -> 0
A51: Net Profit/Loss | D51: =SUM(D5:D44) -> 0
A52: Number of Transactions | D52: =SUMPRODUCT(--((ISNUMBER(B5:B44)+ISNUMBER(C5:C44))>0)) -> 0

Sheet 21-Jan
A1: 🇦🇪 AED — UAE Dirham | C1: 🇮🇳 INR — Indian Rupee
A2: EXCHANGE RATE | B2: 1 AED = | D2: =IF(N(C2)>0,"","◄ enter today's rate") -> ◄ enter today's rate
A3: Yellow cell and blue figures are yours to type; everything else calculates automatically. Profit / Loss = AED Received × Rate − INR Given (100 AED at 25, ₹2,400 given → +₹100)
A4: Name | B4: AED Received | C4: INR Given | D4: Profit / Loss
D5: =IF(AND(ISNUMBER(B5),ISNUMBER(C5),N($C$2)>0),ROUND(B5*$C$2-C5,2),"")
D6: =IF(AND(ISNUMBER(B6),ISNUMBER(C6),N($C$2)>0),ROUND(B6*$C$2-C6,2),"")
D7: =IF(AND(ISNUMBER(B7),ISNUMBER(C7),N($C$2)>0),ROUND(B7*$C$2-C7,2),"")
D8: =IF(AND(ISNUMBER(B8),ISNUMBER(C8),N($C$2)>0),ROUND(B8*$C$2-C8,2),"")
D9: =IF(AND(ISNUMBER(B9),ISNUMBER(C9),N($C$2)>0),ROUND(B9*$C$2-C9,2),"")
D10: =IF(AND(ISNUMBER(B10),ISNUMBER(C10),N($C$2)>0),ROUND(B10*$C$2-C10,2),"")
D11: =IF(AND(ISNUMBER(B11),ISNUMBER(C11),N($C$2)>0),ROUND(B11*$C$2-C11,2),"")
D12: =IF(AND(ISNUMBER(B12),ISNUMBER(C12),N($C$2)>0),ROUND(B12*$C$2-C12,2),"")
D13: =IF(AND(ISNUMBER(B13),ISNUMBER(C13),N($C$2)>0),ROUND(B13*$C$2-C13,2),"")
D14: =IF(AND(ISNUMBER(B14),ISNUMBER(C14),N($C$2)>0),ROUND(B14*$C$2-C14,2),"")
D15: =IF(AND(ISNUMBER(B15),ISNUMBER(C15),N($C$2)>0),ROUND(B15*$C$2-C15,2),"")
D16: =IF(AND(ISNUMBER(B16),ISNUMBER(C16),N($C$2)>0),ROUND(B16*$C$2-C16,2),"")
... D44: =IF(AND(ISNUMBER(B44),ISNUMBER(C44),N($C$2)>0),ROUND(B44*$C$2-C44,2),"")
A46: DAILY TOTALS
A47: Total AED Received | D47: =SUM(B5:B44) -> 0
A48: Total INR Given | D48: =SUM(C5:C44) -> 0
A49: Total Profit | D49: =SUMIF(D5:D44,">0") -> 0
A50: Total Loss | D50: =SUMIF(D5:D44,"<0") -> 0
A51: Net Profit/Loss | D51: =SUM(D5:D44) -> 0
A52: Number of Transactions | D52: =SUMPRODUCT(--((ISNUMBER(B5:B44)+ISNUMBER(C5:C44))>0)) -> 0

Sheet 22-Jan
A1: 🇦🇪 AED — UAE Dirham | C1: 🇮🇳 INR — Indian Rupee
A2: EXCHANGE RATE | B2: 1 AED = | D2: =IF(N(C2)>0,"","◄ enter today's rate") -> ◄ enter today's rate
A3: Yellow cell and blue figures are yours to type; everything else calculates automatically. Profit / Loss = AED Received × Rate − INR Given (100 AED at 25, ₹2,400 given → +₹100)
A4: Name | B4: AED Received | C4: INR Given | D4: Profit / Loss
D5: =IF(AND(ISNUMBER(B5),ISNUMBER(C5),N($C$2)>0),ROUND(B5*$C$2-C5,2),"")
D6: =IF(AND(ISNUMBER(B6),ISNUMBER(C6),N($C$2)>0),ROUND(B6*$C$2-C6,2),"")
D7: =IF(AND(ISNUMBER(B7),ISNUMBER(C7),N($C$2)>0),ROUND(B7*$C$2-C7,2),"")
D8: =IF(AND(ISNUMBER(B8),ISNUMBER(C8),N($C$2)>0),ROUND(B8*$C$2-C8,2),"")
D9: =IF(AND(ISNUMBER(B9),ISNUMBER(C9),N($C$2)>0),ROUND(B9*$C$2-C9,2),"")
D10: =IF(AND(ISNUMBER(B10),ISNUMBER(C10),N($C$2)>0),ROUND(B10*$C$2-C10,2),"")
D11: =IF(AND(ISNUMBER(B11),ISNUMBER(C11),N($C$2)>0),ROUND(B11*$C$2-C11,2),"")
D12: =IF(AND(ISNUMBER(B12),ISNUMBER(C12),N($C$2)>0),ROUND(B12*$C$2-C12,2),"")
D13: =IF(AND(ISNUMBER(B13),ISNUMBER(C13),N($C$2)>0),ROUND(B13*$C$2-C13,2),"")
D14: =IF(AND(ISNUMBER(B14),ISNUMBER(C14),N($C$2)>0),ROUND(B14*$C$2-C14,2),"")
D15: =IF(AND(ISNUMBER(B15),ISNUMBER(C15),N($C$2)>0),ROUND(B15*$C$2-C15,2),"")
D16: =IF(AND(ISNUMBER(B16),ISNUMBER(C16),N($C$2)>0),ROUND(B16*$C$2-C16,2),"")
... D44: =IF(AND(ISNUMBER(B44),ISNUMBER(C44),N($C$2)>0),ROUND(B44*$C$2-C44,2),"")
A46: DAILY TOTALS
A47: Total AED Received | D47: =SUM(B5:B44) -> 0
A48: Total INR Given | D48: =SUM(C5:C44) -> 0
A49: Total Profit | D49: =SUMIF(D5:D44,">0") -> 0
A50: Total Loss | D50: =SUMIF(D5:D44,"<0") -> 0
A51: Net Profit/Loss | D51: =SUM(D5:D44) -> 0
A52: Number of Transactions | D52: =SUMPRODUCT(--((ISNUMBER(B5:B44)+ISNUMBER(C5:C44))>0)) -> 0

Sheet 23-Jan
A1: 🇦🇪 AED — UAE Dirham | C1: 🇮🇳 INR — Indian Rupee
A2: EXCHANGE RATE | B2: 1 AED = | D2: =IF(N(C2)>0,"","◄ enter today's rate") -> ◄ enter today's rate
A3: Yellow cell and blue figures are yours to type; everything else calculates automatically. Profit / Loss = AED Received × Rate − INR Given (100 AED at 25, ₹2,400 given → +₹100)
A4: Name | B4: AED Received | C4: INR Given | D4: Profit / Loss
D5: =IF(AND(ISNUMBER(B5),ISNUMBER(C5),N($C$2)>0),ROUND(B5*$C$2-C5,2),"")
D6: =IF(AND(ISNUMBER(B6),ISNUMBER(C6),N($C$2)>0),ROUND(B6*$C$2-C6,2),"")
D7: =IF(AND(ISNUMBER(B7),ISNUMBER(C7),N($C$2)>0),ROUND(B7*$C$2-C7,2),"")
D8: =IF(AND(ISNUMBER(B8),ISNUMBER(C8),N($C$2)>0),ROUND(B8*$C$2-C8,2),"")
D9: =IF(AND(ISNUMBER(B9),ISNUMBER(C9),N($C$2)>0),ROUND(B9*$C$2-C9,2),"")
D10: =IF(AND(ISNUMBER(B10),ISNUMBER(C10),N($C$2)>0),ROUND(B10*$C$2-C10,2),"")
D11: =IF(AND(ISNUMBER(B11),ISNUMBER(C11),N($C$2)>0),ROUND(B11*$C$2-C11,2),"")
D12: =IF(AND(ISNUMBER(B12),ISNUMBER(C12),N($C$2)>0),ROUND(B12*$C$2-C12,2),"")
D13: =IF(AND(ISNUMBER(B13),ISNUMBER(C13),N($C$2)>0),ROUND(B13*$C$2-C13,2),"")
D14: =IF(AND(ISNUMBER(B14),ISNUMBER(C14),N($C$2)>0),ROUND(B14*$C$2-C14,2),"")
D15: =IF(AND(ISNUMBER(B15),ISNUMBER(C15),N($C$2)>0),ROUND(B15*$C$2-C15,2),"")
D16: =IF(AND(ISNUMBER(B16),ISNUMBER(C16),N($C$2)>0),ROUND(B16*$C$2-C16,2),"")
... D44: =IF(AND(ISNUMBER(B44),ISNUMBER(C44),N($C$2)>0),ROUND(B44*$C$2-C44,2),"")
A46: DAILY TOTALS
A47: Total AED Received | D47: =SUM(B5:B44) -> 0
A48: Total INR Given | D48: =SUM(C5:C44) -> 0
A49: Total Profit | D49: =SUMIF(D5:D44,">0") -> 0
A50: Total Loss | D50: =SUMIF(D5:D44,"<0") -> 0
A51: Net Profit/Loss | D51: =SUM(D5:D44) -> 0
A52: Number of Transactions | D52: =SUMPRODUCT(--((ISNUMBER(B5:B44)+ISNUMBER(C5:C44))>0)) -> 0

Sheet 24-Jan
A1: 🇦🇪 AED — UAE Dirham | C1: 🇮🇳 INR — Indian Rupee
A2: EXCHANGE RATE | B2: 1 AED = | D2: =IF(N(C2)>0,"","◄ enter today's rate") -> ◄ enter today's rate
A3: Yellow cell and blue figures are yours to type; everything else calculates automatically. Profit / Loss = AED Received × Rate − INR Given (100 AED at 25, ₹2,400 given → +₹100)
A4: Name | B4: AED Received | C4: INR Given | D4: Profit / Loss
D5: =IF(AND(ISNUMBER(B5),ISNUMBER(C5),N($C$2)>0),ROUND(B5*$C$2-C5,2),"")
D6: =IF(AND(ISNUMBER(B6),ISNUMBER(C6),N($C$2)>0),ROUND(B6*$C$2-C6,2),"")
D7: =IF(AND(ISNUMBER(B7),ISNUMBER(C7),N($C$2)>0),ROUND(B7*$C$2-C7,2),"")
D8: =IF(AND(ISNUMBER(B8),ISNUMBER(C8),N($C$2)>0),ROUND(B8*$C$2-C8,2),"")
D9: =IF(AND(ISNUMBER(B9),ISNUMBER(C9),N($C$2)>0),ROUND(B9*$C$2-C9,2),"")
D10: =IF(AND(ISNUMBER(B10),ISNUMBER(C10),N($C$2)>0),ROUND(B10*$C$2-C10,2),"")
D11: =IF(AND(ISNUMBER(B11),ISNUMBER(C11),N($C$2)>0),ROUND(B11*$C$2-C11,2),"")
D12: =IF(AND(ISNUMBER(B12),ISNUMBER(C12),N($C$2)>0),ROUND(B12*$C$2-C12,2),"")
D13: =IF(AND(ISNUMBER(B13),ISNUMBER(C13),N($C$2)>0),ROUND(B13*$C$2-C13,2),"")
D14: =IF(AND(ISNUMBER(B14),ISNUMBER(C14),N($C$2)>0),ROUND(B14*$C$2-C14,2),"")
D15: =IF(AND(ISNUMBER(B15),ISNUMBER(C15),N($C$2)>0),ROUND(B15*$C$2-C15,2),"")
D16: =IF(AND(ISNUMBER(B16),ISNUMBER(C16),N($C$2)>0),ROUND(B16*$C$2-C16,2),"")
... D44: =IF(AND(ISNUMBER(B44),ISNUMBER(C44),N($C$2)>0),ROUND(B44*$C$2-C44,2),"")
A46: DAILY TOTALS
A47: Total AED Received | D47: =SUM(B5:B44) -> 0
A48: Total INR Given | D48: =SUM(C5:C44) -> 0
A49: Total Profit | D49: =SUMIF(D5:D44,">0") -> 0
A50: Total Loss | D50: =SUMIF(D5:D44,"<0") -> 0
A51: Net Profit/Loss | D51: =SUM(D5:D44) -> 0
A52: Number of Transactions | D52: =SUMPRODUCT(--((ISNUMBER(B5:B44)+ISNUMBER(C5:C44))>0)) -> 0

Sheet 25-Jan
A1: 🇦🇪 AED — UAE Dirham | C1: 🇮🇳 INR — Indian Rupee
A2: EXCHANGE RATE | B2: 1 AED = | D2: =IF(N(C2)>0,"","◄ enter today's rate") -> ◄ enter today's rate
A3: Yellow cell and blue figures are yours to type; everything else calculates automatically. Profit / Loss = AED Received × Rate − INR Given (100 AED at 25, ₹2,400 given → +₹100)
A4: Name | B4: AED Received | C4: INR Given | D4: Profit / Loss
D5: =IF(AND(ISNUMBER(B5),ISNUMBER(C5),N($C$2)>0),ROUND(B5*$C$2-C5,2),"")
D6: =IF(AND(ISNUMBER(B6),ISNUMBER(C6),N($C$2)>0),ROUND(B6*$C$2-C6,2),"")
D7: =IF(AND(ISNUMBER(B7),ISNUMBER(C7),N($C$2)>0),ROUND(B7*$C$2-C7,2),"")
D8: =IF(AND(ISNUMBER(B8),ISNUMBER(C8),N($C$2)>0),ROUND(B8*$C$2-C8,2),"")
D9: =IF(AND(ISNUMBER(B9),ISNUMBER(C9),N($C$2)>0),ROUND(B9*$C$2-C9,2),"")
D10: =IF(AND(ISNUMBER(B10),ISNUMBER(C10),N($C$2)>0),ROUND(B10*$C$2-C10,2),"")
D11: =IF(AND(ISNUMBER(B11),ISNUMBER(C11),N($C$2)>0),ROUND(B11*$C$2-C11,2),"")
D12: =IF(AND(ISNUMBER(B12),ISNUMBER(C12),N($C$2)>0),ROUND(B12*$C$2-C12,2),"")
D13: =IF(AND(ISNUMBER(B13),ISNUMBER(C13),N($C$2)>0),ROUND(B13*$C$2-C13,2),"")
D14: =IF(AND(ISNUMBER(B14),ISNUMBER(C14),N($C$2)>0),ROUND(B14*$C$2-C14,2),"")
D15: =IF(AND(ISNUMBER(B15),ISNUMBER(C15),N($C$2)>0),ROUND(B15*$C$2-C15,2),"")
D16: =IF(AND(ISNUMBER(B16),ISNUMBER(C16),N($C$2)>0),ROUND(B16*$C$2-C16,2),"")
... D44: =IF(AND(ISNUMBER(B44),ISNUMBER(C44),N($C$2)>0),ROUND(B44*$C$2-C44,2),"")
A46: DAILY TOTALS
A47: Total AED Received | D47: =SUM(B5:B44) -> 0
A48: Total INR Given | D48: =SUM(C5:C44) -> 0
A49: Total Profit | D49: =SUMIF(D5:D44,">0") -> 0
A50: Total Loss | D50: =SUMIF(D5:D44,"<0") -> 0
A51: Net Profit/Loss | D51: =SUM(D5:D44) -> 0
A52: Number of Transactions | D52: =SUMPRODUCT(--((ISNUMBER(B5:B44)+ISNUMBER(C5:C44))>0)) -> 0

Sheet 26-Jan
A1: 🇦🇪 AED — UAE Dirham | C1: 🇮🇳 INR — Indian Rupee
A2: EXCHANGE RATE | B2: 1 AED = | D2: =IF(N(C2)>0,"","◄ enter today's rate") -> ◄ enter today's rate
A3: Yellow cell and blue figures are yours to type; everything else calculates automatically. Profit / Loss = AED Received × Rate − INR Given (100 AED at 25, ₹2,400 given → +₹100)
A4: Name | B4: AED Received | C4: INR Given | D4: Profit / Loss
D5: =IF(AND(ISNUMBER(B5),ISNUMBER(C5),N($C$2)>0),ROUND(B5*$C$2-C5,2),"")
D6: =IF(AND(ISNUMBER(B6),ISNUMBER(C6),N($C$2)>0),ROUND(B6*$C$2-C6,2),"")
D7: =IF(AND(ISNUMBER(B7),ISNUMBER(C7),N($C$2)>0),ROUND(B7*$C$2-C7,2),"")
D8: =IF(AND(ISNUMBER(B8),ISNUMBER(C8),N($C$2)>0),ROUND(B8*$C$2-C8,2),"")
D9: =IF(AND(ISNUMBER(B9),ISNUMBER(C9),N($C$2)>0),ROUND(B9*$C$2-C9,2),"")
D10: =IF(AND(ISNUMBER(B10),ISNUMBER(C10),N($C$2)>0),ROUND(B10*$C$2-C10,2),"")
D11: =IF(AND(ISNUMBER(B11),ISNUMBER(C11),N($C$2)>0),ROUND(B11*$C$2-C11,2),"")
D12: =IF(AND(ISNUMBER(B12),ISNUMBER(C12),N($C$2)>0),ROUND(B12*$C$2-C12,2),"")
D13: =IF(AND(ISNUMBER(B13),ISNUMBER(C13),N($C$2)>0),ROUND(B13*$C$2-C13,2),"")
D14: =IF(AND(ISNUMBER(B14),ISNUMBER(C14),N($C$2)>0),ROUND(B14*$C$2-C14,2),"")
D15: =IF(AND(ISNUMBER(B15),ISNUMBER(C15),N($C$2)>0),ROUND(B15*$C$2-C15,2),"")
D16: =IF(AND(ISNUMBER(B16),ISNUMBER(C16),N($C$2)>0),ROUND(B16*$C$2-C16,2),"")
... D44: =IF(AND(ISNUMBER(B44),ISNUMBER(C44),N($C$2)>0),ROUND(B44*$C$2-C44,2),"")
A46: DAILY TOTALS
A47: Total AED Received | D47: =SUM(B5:B44) -> 0
A48: Total INR Given | D48: =SUM(C5:C44) -> 0
A49: Total Profit | D49: =SUMIF(D5:D44,">0") -> 0
A50: Total Loss | D50: =SUMIF(D5:D44,"<0") -> 0
A51: Net Profit/Loss | D51: =SUM(D5:D44) -> 0
A52: Number of Transactions | D52: =SUMPRODUCT(--((ISNUMBER(B5:B44)+ISNUMBER(C5:C44))>0)) -> 0

Sheet 27-Jan
A1: 🇦🇪 AED — UAE Dirham | C1: 🇮🇳 INR — Indian Rupee
A2: EXCHANGE RATE | B2: 1 AED = | D2: =IF(N(C2)>0,"","◄ enter today's rate") -> ◄ enter today's rate
A3: Yellow cell and blue figures are yours to type; everything else calculates automatically. Profit / Loss = AED Received × Rate − INR Given (100 AED at 25, ₹2,400 given → +₹100)
A4: Name | B4: AED Received | C4: INR Given | D4: Profit / Loss
D5: =IF(AND(ISNUMBER(B5),ISNUMBER(C5),N($C$2)>0),ROUND(B5*$C$2-C5,2),"")
D6: =IF(AND(ISNUMBER(B6),ISNUMBER(C6),N($C$2)>0),ROUND(B6*$C$2-C6,2),"")
D7: =IF(AND(ISNUMBER(B7),ISNUMBER(C7),N($C$2)>0),ROUND(B7*$C$2-C7,2),"")
D8: =IF(AND(ISNUMBER(B8),ISNUMBER(C8),N($C$2)>0),ROUND(B8*$C$2-C8,2),"")
D9: =IF(AND(ISNUMBER(B9),ISNUMBER(C9),N($C$2)>0),ROUND(B9*$C$2-C9,2),"")
D10: =IF(AND(ISNUMBER(B10),ISNUMBER(C10),N($C$2)>0),ROUND(B10*$C$2-C10,2),"")
D11: =IF(AND(ISNUMBER(B11),ISNUMBER(C11),N($C$2)>0),ROUND(B11*$C$2-C11,2),"")
D12: =IF(AND(ISNUMBER(B12),ISNUMBER(C12),N($C$2)>0),ROUND(B12*$C$2-C12,2),"")
D13: =IF(AND(ISNUMBER(B13),ISNUMBER(C13),N($C$2)>0),ROUND(B13*$C$2-C13,2),"")
D14: =IF(AND(ISNUMBER(B14),ISNUMBER(C14),N($C$2)>0),ROUND(B14*$C$2-C14,2),"")
D15: =IF(AND(ISNUMBER(B15),ISNUMBER(C15),N($C$2)>0),ROUND(B15*$C$2-C15,2),"")
D16: =IF(AND(ISNUMBER(B16),ISNUMBER(C16),N($C$2)>0),ROUND(B16*$C$2-C16,2),"")
... D44: =IF(AND(ISNUMBER(B44),ISNUMBER(C44),N($C$2)>0),ROUND(B44*$C$2-C44,2),"")
A46: DAILY TOTALS
A47: Total AED Received | D47: =SUM(B5:B44) -> 0
A48: Total INR Given | D48: =SUM(C5:C44) -> 0
A49: Total Profit | D49: =SUMIF(D5:D44,">0") -> 0
A50: Total Loss | D50: =SUMIF(D5:D44,"<0") -> 0
A51: Net Profit/Loss | D51: =SUM(D5:D44) -> 0
A52: Number of Transactions | D52: =SUMPRODUCT(--((ISNUMBER(B5:B44)+ISNUMBER(C5:C44))>0)) -> 0

Sheet 28-Jan
A1: 🇦🇪 AED — UAE Dirham | C1: 🇮🇳 INR — Indian Rupee
A2: EXCHANGE RATE | B2: 1 AED = | D2: =IF(N(C2)>0,"","◄ enter today's rate") -> ◄ enter today's rate
A3: Yellow cell and blue figures are yours to type; everything else calculates automatically. Profit / Loss = AED Received × Rate − INR Given (100 AED at 25, ₹2,400 given → +₹100)
A4: Name | B4: AED Received | C4: INR Given | D4: Profit / Loss
D5: =IF(AND(ISNUMBER(B5),ISNUMBER(C5),N($C$2)>0),ROUND(B5*$C$2-C5,2),"")
D6: =IF(AND(ISNUMBER(B6),ISNUMBER(C6),N($C$2)>0),ROUND(B6*$C$2-C6,2),"")
D7: =IF(AND(ISNUMBER(B7),ISNUMBER(C7),N($C$2)>0),ROUND(B7*$C$2-C7,2),"")
D8: =IF(AND(ISNUMBER(B8),ISNUMBER(C8),N($C$2)>0),ROUND(B8*$C$2-C8,2),"")
D9: =IF(AND(ISNUMBER(B9),ISNUMBER(C9),N($C$2)>0),ROUND(B9*$C$2-C9,2),"")
D10: =IF(AND(ISNUMBER(B10),ISNUMBER(C10),N($C$2)>0),ROUND(B10*$C$2-C10,2),"")
D11: =IF(AND(ISNUMBER(B11),ISNUMBER(C11),N($C$2)>0),ROUND(B11*$C$2-C11,2),"")
D12: =IF(AND(ISNUMBER(B12),ISNUMBER(C12),N($C$2)>0),ROUND(B12*$C$2-C12,2),"")
D13: =IF(AND(ISNUMBER(B13),ISNUMBER(C13),N($C$2)>0),ROUND(B13*$C$2-C13,2),"")
D14: =IF(AND(ISNUMBER(B14),ISNUMBER(C14),N($C$2)>0),ROUND(B14*$C$2-C14,2),"")
D15: =IF(AND(ISNUMBER(B15),ISNUMBER(C15),N($C$2)>0),ROUND(B15*$C$2-C15,2),"")
D16: =IF(AND(ISNUMBER(B16),ISNUMBER(C16),N($C$2)>0),ROUND(B16*$C$2-C16,2),"")
... D44: =IF(AND(ISNUMBER(B44),ISNUMBER(C44),N($C$2)>0),ROUND(B44*$C$2-C44,2),"")
A46: DAILY TOTALS
A47: Total AED Received | D47: =SUM(B5:B44) -> 0
A48: Total INR Given | D48: =SUM(C5:C44) -> 0
A49: Total Profit | D49: =SUMIF(D5:D44,">0") -> 0
A50: Total Loss | D50: =SUMIF(D5:D44,"<0") -> 0
A51: Net Profit/Loss | D51: =SUM(D5:D44) -> 0
A52: Number of Transactions | D52: =SUMPRODUCT(--((ISNUMBER(B5:B44)+ISNUMBER(C5:C44))>0)) -> 0

Sheet 29-Jan
A1: 🇦🇪 AED — UAE Dirham | C1: 🇮🇳 INR — Indian Rupee
A2: EXCHANGE RATE | B2: 1 AED = | D2: =IF(N(C2)>0,"","◄ enter today's rate") -> ◄ enter today's rate
A3: Yellow cell and blue figures are yours to type; everything else calculates automatically. Profit / Loss = AED Received × Rate − INR Given (100 AED at 25, ₹2,400 given → +₹100)
A4: Name | B4: AED Received | C4: INR Given | D4: Profit / Loss
D5: =IF(AND(ISNUMBER(B5),ISNUMBER(C5),N($C$2)>0),ROUND(B5*$C$2-C5,2),"")
D6: =IF(AND(ISNUMBER(B6),ISNUMBER(C6),N($C$2)>0),ROUND(B6*$C$2-C6,2),"")
D7: =IF(AND(ISNUMBER(B7),ISNUMBER(C7),N($C$2)>0),ROUND(B7*$C$2-C7,2),"")
D8: =IF(AND(ISNUMBER(B8),ISNUMBER(C8),N($C$2)>0),ROUND(B8*$C$2-C8,2),"")
D9: =IF(AND(ISNUMBER(B9),ISNUMBER(C9),N($C$2)>0),ROUND(B9*$C$2-C9,2),"")
D10: =IF(AND(ISNUMBER(B10),ISNUMBER(C10),N($C$2)>0),ROUND(B10*$C$2-C10,2),"")
D11: =IF(AND(ISNUMBER(B11),ISNUMBER(C11),N($C$2)>0),ROUND(B11*$C$2-C11,2),"")
D12: =IF(AND(ISNUMBER(B12),ISNUMBER(C12),N($C$2)>0),ROUND(B12*$C$2-C12,2),"")
D13: =IF(AND(ISNUMBER(B13),ISNUMBER(C13),N($C$2)>0),ROUND(B13*$C$2-C13,2),"")
D14: =IF(AND(ISNUMBER(B14),ISNUMBER(C14),N($C$2)>0),ROUND(B14*$C$2-C14,2),"")
D15: =IF(AND(ISNUMBER(B15),ISNUMBER(C15),N($C$2)>0),ROUND(B15*$C$2-C15,2),"")
D16: =IF(AND(ISNUMBER(B16),ISNUMBER(C16),N($C$2)>0),ROUND(B16*$C$2-C16,2),"")
... D44: =IF(AND(ISNUMBER(B44),ISNUMBER(C44),N($C$2)>0),ROUND(B44*$C$2-C44,2),"")
A46: DAILY TOTALS
A47: Total AED Received | D47: =SUM(B5:B44) -> 0
A48: Total INR Given | D48: =SUM(C5:C44) -> 0
A49: Total Profit | D49: =SUMIF(D5:D44,">0") -> 0
A50: Total Loss | D50: =SUMIF(D5:D44,"<0") -> 0
A51: Net Profit/Loss | D51: =SUM(D5:D44) -> 0
A52: Number of Transactions | D52: =SUMPRODUCT(--((ISNUMBER(B5:B44)+ISNUMBER(C5:C44))>0)) -> 0

Sheet 30-Jan
A1: 🇦🇪 AED — UAE Dirham | C1: 🇮🇳 INR — Indian Rupee
A2: EXCHANGE RATE | B2: 1 AED = | D2: =IF(N(C2)>0,"","◄ enter today's rate") -> ◄ enter today's rate
A3: Yellow cell and blue figures are yours to type; everything else calculates automatically. Profit / Loss = AED Received × Rate − INR Given (100 AED at 25, ₹2,400 given → +₹100)
A4: Name | B4: AED Received | C4: INR Given | D4: Profit / Loss
D5: =IF(AND(ISNUMBER(B5),ISNUMBER(C5),N($C$2)>0),ROUND(B5*$C$2-C5,2),"")
D6: =IF(AND(ISNUMBER(B6),ISNUMBER(C6),N($C$2)>0),ROUND(B6*$C$2-C6,2),"")
D7: =IF(AND(ISNUMBER(B7),ISNUMBER(C7),N($C$2)>0),ROUND(B7*$C$2-C7,2),"")
D8: =IF(AND(ISNUMBER(B8),ISNUMBER(C8),N($C$2)>0),ROUND(B8*$C$2-C8,2),"")
D9: =IF(AND(ISNUMBER(B9),ISNUMBER(C9),N($C$2)>0),ROUND(B9*$C$2-C9,2),"")
D10: =IF(AND(ISNUMBER(B10),ISNUMBER(C10),N($C$2)>0),ROUND(B10*$C$2-C10,2),"")
D11: =IF(AND(ISNUMBER(B11),ISNUMBER(C11),N($C$2)>0),ROUND(B11*$C$2-C11,2),"")
D12: =IF(AND(ISNUMBER(B12),ISNUMBER(C12),N($C$2)>0),ROUND(B12*$C$2-C12,2),"")
D13: =IF(AND(ISNUMBER(B13),ISNUMBER(C13),N($C$2)>0),ROUND(B13*$C$2-C13,2),"")
D14: =IF(AND(ISNUMBER(B14),ISNUMBER(C14),N($C$2)>0),ROUND(B14*$C$2-C14,2),"")
D15: =IF(AND(ISNUMBER(B15),ISNUMBER(C15),N($C$2)>0),ROUND(B15*$C$2-C15,2),"")
D16: =IF(AND(ISNUMBER(B16),ISNUMBER(C16),N($C$2)>0),ROUND(B16*$C$2-C16,2),"")
... D44: =IF(AND(ISNUMBER(B44),ISNUMBER(C44),N($C$2)>0),ROUND(B44*$C$2-C44,2),"")
A46: DAILY TOTALS
A47: Total AED Received | D47: =SUM(B5:B44) -> 0
A48: Total INR Given | D48: =SUM(C5:C44) -> 0
A49: Total Profit | D49: =SUMIF(D5:D44,">0") -> 0
A50: Total Loss | D50: =SUMIF(D5:D44,"<0") -> 0
A51: Net Profit/Loss | D51: =SUM(D5:D44) -> 0
A52: Number of Transactions | D52: =SUMPRODUCT(--((ISNUMBER(B5:B44)+ISNUMBER(C5:C44))>0)) -> 0

Sheet 31-Jan
A1: 🇦🇪 AED — UAE Dirham | C1: 🇮🇳 INR — Indian Rupee
A2: EXCHANGE RATE | B2: 1 AED = | D2: =IF(N(C2)>0,"","◄ enter today's rate") -> ◄ enter today's rate
A3: Yellow cell and blue figures are yours to type; everything else calculates automatically. Profit / Loss = AED Received × Rate − INR Given (100 AED at 25, ₹2,400 given → +₹100)
A4: Name | B4: AED Received | C4: INR Given | D4: Profit / Loss
D5: =IF(AND(ISNUMBER(B5),ISNUMBER(C5),N($C$2)>0),ROUND(B5*$C$2-C5,2),"")
D6: =IF(AND(ISNUMBER(B6),ISNUMBER(C6),N($C$2)>0),ROUND(B6*$C$2-C6,2),"")
D7: =IF(AND(ISNUMBER(B7),ISNUMBER(C7),N($C$2)>0),ROUND(B7*$C$2-C7,2),"")
D8: =IF(AND(ISNUMBER(B8),ISNUMBER(C8),N($C$2)>0),ROUND(B8*$C$2-C8,2),"")
D9: =IF(AND(ISNUMBER(B9),ISNUMBER(C9),N($C$2)>0),ROUND(B9*$C$2-C9,2),"")
D10: =IF(AND(ISNUMBER(B10),ISNUMBER(C10),N($C$2)>0),ROUND(B10*$C$2-C10,2),"")
D11: =IF(AND(ISNUMBER(B11),ISNUMBER(C11),N($C$2)>0),ROUND(B11*$C$2-C11,2),"")
D12: =IF(AND(ISNUMBER(B12),ISNUMBER(C12),N($C$2)>0),ROUND(B12*$C$2-C12,2),"")
D13: =IF(AND(ISNUMBER(B13),ISNUMBER(C13),N($C$2)>0),ROUND(B13*$C$2-C13,2),"")
D14: =IF(AND(ISNUMBER(B14),ISNUMBER(C14),N($C$2)>0),ROUND(B14*$C$2-C14,2),"")
D15: =IF(AND(ISNUMBER(B15),ISNUMBER(C15),N($C$2)>0),ROUND(B15*$C$2-C15,2),"")
D16: =IF(AND(ISNUMBER(B16),ISNUMBER(C16),N($C$2)>0),ROUND(B16*$C$2-C16,2),"")
... D44: =IF(AND(ISNUMBER(B44),ISNUMBER(C44),N($C$2)>0),ROUND(B44*$C$2-C44,2),"")
A46: DAILY TOTALS
A47: Total AED Received | D47: =SUM(B5:B44) -> 0
A48: Total INR Given | D48: =SUM(C5:C44) -> 0
A49: Total Profit | D49: =SUMIF(D5:D44,">0") -> 0
A50: Total Loss | D50: =SUMIF(D5:D44,"<0") -> 0
